<?xml version="1.0" ?>
<robot name="viper300_sysid">
  <!-- Generated by phi_to_urdf.py on 2026-05-18 16:01:06 -->
  <link name="base_link">
    <inertial>
      <mass value="0.0" />
      <inertia ixx="0" ixy="0" ixz="0" iyy="0" iyz="0" izz="0" />
    </inertial>
  </link>
  <joint name="waist" type="revolute">
    <origin xyz="0.00000000 0.00000000 0.12675000" rpy="0.00000000 -0.00000000 0.00000000" />
    <parent link="base_link" />
    <child link="waist_link" />
    <axis xyz="0 0 1" />
    <limit lower="-3.141590" upper="3.141590" effort="4.100" velocity="3.141590" />
    <dynamics damping="0.06799754" friction="1.58767594" />
  </joint>
  <link name="waist_link">
    <inertial>
      <origin xyz="-0.00669549 0.00390979 0.87654940" rpy="0 0 0" />
      <mass value="0.34155359" />
      <inertia ixx="0.0138800922" ixy="-0.0000003910" ixz="-0.0000285393" iyy="0.0138804590" iyz="-0.0000399510" izz="0.0016811651" />
    </inertial>
    <!-- Identified torque offset F0[1] = 0.159969 Nm (feed-forward term, add manually to your controller) -->
  </link>
  <joint name="shoulder" type="revolute">
    <origin xyz="0.00000000 -0.00000000 0.00000000" rpy="-1.57079633 -0.00000000 -1.37287599" />
    <parent link="waist_link" />
    <child link="upper_arm_link" />
    <axis xyz="0 0 1" />
    <limit lower="-1.876300" upper="1.989700" effort="10.600" velocity="2.610500" />
    <dynamics damping="0.12278967" friction="0.76852746" />
  </joint>
  <link name="upper_arm_link">
    <inertial>
      <origin xyz="0.03459168 0.01704109 0.00174032" rpy="0 0 0" />
      <mass value="0.41364634" />
      <inertia ixx="0.0167845351" ixy="0.0005757447" ixz="-0.0000964409" iyy="0.0010193197" iyz="0.0002257820" izz="0.0166061789" />
    </inertial>
    <!-- Identified torque offset F0[2] = -0.449287 Nm (feed-forward term, add manually to your controller) -->
  </link>
  <joint name="elbow" type="revolute">
    <origin xyz="0.29996732 -0.06015719 0.00000000" rpy="0.00000000 -0.00000000 -0.19792034" />
    <parent link="upper_arm_link" />
    <child link="forearm_link" />
    <axis xyz="0 0 1" />
    <limit lower="-2.152100" upper="1.570800" effort="10.600" velocity="2.610500" />
    <dynamics damping="0.05872572" friction="1.74629723" />
  </joint>
  <link name="forearm_link">
    <inertial>
      <origin xyz="-0.07171595 0.12061905 -0.01991252" rpy="0 0 0" />
      <mass value="0.02387846" />
      <inertia ixx="0.0028873876" ixy="0.0004023267" ixz="-0.0001643519" iyy="0.0016377490" iyz="0.0005137632" izz="0.0031238845" />
    </inertial>
    <!-- Identified torque offset F0[3] = -4.031327 Nm (feed-forward term, add manually to your controller) -->
  </link>
  <joint name="forearm_roll" type="revolute">
    <origin xyz="0.00000000 0.00000000 0.30002000" rpy="-1.57079633 -0.00000000 0.00000000" />
    <parent link="forearm_link" />
    <child link="wrist_link" />
    <axis xyz="0 0 1" />
    <limit lower="-3.141590" upper="3.141590" effort="4.100" velocity="3.141590" />
    <dynamics damping="1.75904986" friction="6.35601848" />
  </joint>
  <link name="wrist_link">
    <inertial>
      <origin xyz="0.12728616 -0.13762722 -0.06304930" rpy="0 0 0" />
      <mass value="0.00635016" />
      <inertia ixx="0.0014025460" ixy="0.0003308507" ixz="0.0003823532" iyy="0.0014269545" iyz="-0.0000121753" izz="0.0010065347" />
    </inertial>
    <!-- Identified torque offset F0[4] = 2.726880 Nm (feed-forward term, add manually to your controller) -->
  </link>
  <joint name="wrist_angle" type="revolute">
    <origin xyz="0.00000000 0.00000000 0.00000000" rpy="1.57079633 -0.00000000 0.00000000" />
    <parent link="wrist_link" />
    <child link="gripper_link" />
    <axis xyz="0 0 1" />
    <limit lower="-1.745300" upper="2.146800" effort="4.100" velocity="3.141590" />
    <dynamics damping="0.02202396" friction="2.22559610" />
  </joint>
  <link name="gripper_link">
    <inertial>
      <origin xyz="0.02892778 0.05303017 -0.30241205" rpy="0 0 0" />
      <mass value="0.01157241" />
      <inertia ixx="0.0010592630" ixy="-0.0000083411" ixz="0.0000309879" iyy="0.0009757546" iyz="0.0000470754" izz="0.0009217072" />
    </inertial>
    <!-- Identified torque offset F0[5] = -2.674792 Nm (feed-forward term, add manually to your controller) -->
  </link>
  <joint name="wrist_rotate" type="revolute">
    <origin xyz="0.00000000 0.00000000 0.00000000" rpy="-1.57079633 -0.00000000 0.00000000" />
    <parent link="gripper_link" />
    <child link="ee_arm" />
    <axis xyz="0 0 1" />
    <limit lower="-3.141590" upper="3.141590" effort="4.100" velocity="3.141590" />
    <dynamics damping="0.00415786" friction="0.00318935" />
  </joint>
  <link name="ee_arm">
    <inertial>
      <origin xyz="0.00694369 0.06786699 -0.12475852" rpy="0 0 0" />
      <mass value="0.00708769" />
      <inertia ixx="0.0004842867" ixy="0.0000264024" ixz="0.0000611659" iyy="0.0004838647" iyz="0.0000022985" izz="0.0002456877" />
    </inertial>
    <!-- Identified torque offset F0[6] = -0.002181 Nm (feed-forward term, add manually to your controller) -->
  </link>
  <joint name="ee_arm" type="fixed">
    <origin xyz="0.13658000 0.0 0.0" rpy="0 0 0" />
    <parent link="ee_arm" />
    <child link="ee_link" />
  </joint>
  <link name="ee_link" />
</robot>