<?xml version="1.0" ?>
<robot name="viper300_sysid">
  <!-- Generated by phi_to_urdf.py on 2026-05-15 11:13:34 -->
  <link name="base_link">
    <inertial>
      <mass value="0.0" />
      <inertia ixx="0" ixy="0" ixz="0" iyy="0" iyz="0" izz="0" />
    </inertial>
  </link>
  <joint name="waist" type="revolute">
    <origin xyz="0.00000000 0.00000000 0.12675000" rpy="0.00000000 -0.00000000 0.00000000" />
    <parent link="base_link" />
    <child link="waist_link" />
    <axis xyz="0 0 1" />
    <limit lower="-3.141590" upper="3.141590" effort="4.100" velocity="3.141590" />
    <dynamics damping="0.02335262" friction="0.65623311" />
  </joint>
  <link name="waist_link">
    <inertial>
      <origin xyz="-0.00084718 0.00000445 -0.01004387" rpy="0 0 0" />
      <mass value="2.30023948" />
      <inertia ixx="0.0264505935" ixy="0.0000008125" ixz="-0.0001231036" iyy="0.0264510378" iyz="0.0000853144" izz="-0.0000822983" />
    </inertial>
    <!-- Identified torque offset F0[1] = 0.023713 Nm (feed-forward term, add manually to your controller) -->
  </link>
  <joint name="shoulder" type="revolute">
    <origin xyz="0.00000000 -0.00000000 0.00000000" rpy="-1.57079633 -0.00000000 -1.37287599" />
    <parent link="waist_link" />
    <child link="upper_arm_link" />
    <axis xyz="0 0 1" />
    <limit lower="-1.876300" upper="1.989700" effort="10.600" velocity="2.610500" />
    <dynamics damping="0.00081103" friction="4.15760119" />
  </joint>
  <link name="upper_arm_link">
    <inertial>
      <origin xyz="-0.00270419 -0.12944454 0.00149424" rpy="0 0 0" />
      <mass value="0.29687638" />
      <inertia ixx="0.0071566206" ixy="-0.0002959697" ixz="0.0000017129" iyy="-0.0000475864" iyz="0.0000435457" izz="0.0071684237" />
    </inertial>
    <!-- Identified torque offset F0[2] = -9.567091 Nm (feed-forward term, add manually to your controller) -->
  </link>
  <joint name="elbow" type="revolute">
    <origin xyz="0.29996732 -0.06015719 0.00000000" rpy="0.00000000 -0.00000000 -0.19792034" />
    <parent link="upper_arm_link" />
    <child link="forearm_link" />
    <axis xyz="0 0 1" />
    <limit lower="-2.152100" upper="1.570800" effort="10.600" velocity="2.610500" />
    <dynamics damping="0.00000000" friction="8.29273823" />
  </joint>
  <link name="forearm_link">
    <inertial>
      <origin xyz="-0.23088834 0.06292618 -0.00751053" rpy="0 0 0" />
      <mass value="0.02626949" />
      <inertia ixx="0.0000386046" ixy="-0.0001058925" ixz="-0.0000133796" iyy="0.0000309317" iyz="-0.0000044279" izz="0.0001354242" />
    </inertial>
    <!-- Identified torque offset F0[3] = -46.708036 Nm (feed-forward term, add manually to your controller) -->
  </link>
  <joint name="forearm_roll" type="revolute">
    <origin xyz="0.00000000 0.00000000 0.30002000" rpy="-1.57079633 -0.00000000 0.00000000" />
    <parent link="forearm_link" />
    <child link="wrist_link" />
    <axis xyz="0 0 1" />
    <limit lower="-3.141590" upper="3.141590" effort="4.100" velocity="3.141590" />
    <dynamics damping="0.00000000" friction="3.68403507" />
  </joint>
  <link name="wrist_link">
    <inertial>
      <origin xyz="-0.09853719 0.33486942 -0.09643010" rpy="0 0 0" />
      <mass value="0.05117365" />
      <inertia ixx="-0.0000932937" ixy="-0.0000072660" ixz="-0.0000076703" iyy="-0.0000993386" iyz="-0.0000235895" izz="-0.0001112586" />
    </inertial>
    <!-- Identified torque offset F0[4] = 0.431908 Nm (feed-forward term, add manually to your controller) -->
  </link>
  <joint name="wrist_angle" type="revolute">
    <origin xyz="0.00000000 0.00000000 0.00000000" rpy="1.57079633 -0.00000000 0.00000000" />
    <parent link="wrist_link" />
    <child link="gripper_link" />
    <axis xyz="0 0 1" />
    <limit lower="-1.745300" upper="2.146800" effort="4.100" velocity="3.141590" />
    <dynamics damping="0.00000000" friction="1.82416438" />
  </joint>
  <link name="gripper_link">
    <inertial>
      <origin xyz="-1.07159562 -1.27237644 -0.92024510" rpy="0 0 0" />
      <mass value="0.00014810" />
      <inertia ixx="-0.0002808719" ixy="0.0000533280" ixz="0.0000455711" iyy="-0.0002721437" iyz="0.0000506880" izz="-0.0002905668" />
    </inertial>
    <!-- Identified torque offset F0[5] = -4.739001 Nm (feed-forward term, add manually to your controller) -->
  </link>
  <joint name="wrist_rotate" type="revolute">
    <origin xyz="0.00000000 0.00000000 0.00000000" rpy="-1.57079633 -0.00000000 0.00000000" />
    <parent link="gripper_link" />
    <child link="ee_arm" />
    <axis xyz="0 0 1" />
    <limit lower="-3.141590" upper="3.141590" effort="4.100" velocity="3.141590" />
    <dynamics damping="0.00000000" friction="0.00000000" />
  </joint>
  <link name="ee_arm">
    <inertial>
      <origin xyz="0.13534496 -0.45173946 0.21795634" rpy="0 0 0" />
      <mass value="0.00038270" />
      <inertia ixx="-0.0001408365" ixy="-0.0000111564" ixz="0.0000003865" iyy="-0.0000960574" iyz="-0.0000039642" izz="-0.0000977426" />
    </inertial>
    <!-- Identified torque offset F0[6] = 0.108676 Nm (feed-forward term, add manually to your controller) -->
  </link>
  <joint name="ee_arm" type="fixed">
    <origin xyz="0.13658000 0.0 0.0" rpy="0 0 0" />
    <parent link="ee_arm" />
    <child link="ee_link" />
  </joint>
  <link name="ee_link" />
</robot>