<?xml version="1.0" ?>
<robot name="viper300_sysid">
  <!-- Generated by phi_to_urdf.py on 2026-05-18 09:13:44 -->
  <link name="base_link">
    <inertial>
      <mass value="0.0" />
      <inertia ixx="0" ixy="0" ixz="0" iyy="0" iyz="0" izz="0" />
    </inertial>
  </link>
  <joint name="waist" type="revolute">
    <origin xyz="0.00000000 0.00000000 0.12675000" rpy="0.00000000 -0.00000000 0.00000000" />
    <parent link="base_link" />
    <child link="waist_link" />
    <axis xyz="0 0 1" />
    <limit lower="-3.141590" upper="3.141590" effort="4.100" velocity="3.141590" />
    <dynamics damping="0.02028479" friction="0.65344744" />
  </joint>
  <link name="waist_link">
    <inertial>
      <origin xyz="-0.00376236 0.00031109 -0.03755559" rpy="0 0 0" />
      <mass value="2.60590288" />
      <inertia ixx="0.0085385352" ixy="0.0005857431" ixz="-0.0014170738" iyy="0.0081423417" iyz="-0.0014469457" izz="0.0018565649" />
    </inertial>
    <!-- Identified torque offset F0[1] = 0.023138 Nm (feed-forward term, add manually to your controller) -->
  </link>
  <joint name="shoulder" type="revolute">
    <origin xyz="0.00000000 -0.00000000 0.00000000" rpy="-1.57079633 -0.00000000 -1.37287599" />
    <parent link="waist_link" />
    <child link="upper_arm_link" />
    <axis xyz="0 0 1" />
    <limit lower="-1.876300" upper="1.989700" effort="10.600" velocity="2.610500" />
    <dynamics damping="0.02436239" friction="4.12874537" />
  </joint>
  <link name="upper_arm_link">
    <inertial>
      <origin xyz="0.00095740 0.11847932 -0.00166323" rpy="0 0 0" />
      <mass value="1.33187408" />
      <inertia ixx="0.0136278765" ixy="0.0000636487" ixz="0.0006378086" iyy="-0.0000400872" iyz="0.0003923923" izz="0.0118573365" />
    </inertial>
    <!-- Identified torque offset F0[2] = -9.709506 Nm (feed-forward term, add manually to your controller) -->
  </link>
  <joint name="elbow" type="revolute">
    <origin xyz="0.29996732 -0.06015719 0.00000000" rpy="0.00000000 -0.00000000 -0.19792034" />
    <parent link="upper_arm_link" />
    <child link="forearm_link" />
    <axis xyz="0 0 1" />
    <limit lower="-2.152100" upper="1.570800" effort="10.600" velocity="2.610500" />
    <dynamics damping="0.00000342" friction="8.22042067" />
  </joint>
  <link name="forearm_link">
    <inertial>
      <origin xyz="-0.31944903 0.01278475 0.00348864" rpy="0 0 0" />
      <mass value="0.53217108" />
      <inertia ixx="0.0001203694" ixy="-0.0007580266" ixz="-0.0000873908" iyy="0.0003894973" iyz="0.0003188211" izz="0.0006810904" />
    </inertial>
    <!-- Identified torque offset F0[3] = -48.222478 Nm (feed-forward term, add manually to your controller) -->
  </link>
  <joint name="forearm_roll" type="revolute">
    <origin xyz="0.00000000 0.00000000 0.30002000" rpy="-1.57079633 -0.00000000 0.00000000" />
    <parent link="forearm_link" />
    <child link="wrist_link" />
    <axis xyz="0 0 1" />
    <limit lower="-3.141590" upper="3.141590" effort="4.100" velocity="3.141590" />
    <dynamics damping="0.00004386" friction="3.69389259" />
  </joint>
  <link name="wrist_link">
    <inertial>
      <origin xyz="0.53859551 -0.23083562 -0.28818927" rpy="0 0 0" />
      <mass value="0.00016499" />
      <inertia ixx="-0.0000717950" ixy="-0.0002828151" ixz="0.0001280790" iyy="-0.0002636821" iyz="0.0001677985" izz="-0.0000995683" />
    </inertial>
    <!-- Identified torque offset F0[4] = 0.416969 Nm (feed-forward term, add manually to your controller) -->
  </link>
  <joint name="wrist_angle" type="revolute">
    <origin xyz="0.00000000 0.00000000 0.00000000" rpy="1.57079633 -0.00000000 0.00000000" />
    <parent link="wrist_link" />
    <child link="gripper_link" />
    <axis xyz="0 0 1" />
    <limit lower="-1.745300" upper="2.146800" effort="4.100" velocity="3.141590" />
    <dynamics damping="0.00000177" friction="1.82666655" />
  </joint>
  <link name="gripper_link">
    <inertial>
      <origin xyz="1.21361955 0.40482499 -0.33852158" rpy="0 0 0" />
      <mass value="0.00022496" />
      <inertia ixx="-0.0001946307" ixy="-0.0001866198" ixz="-0.0003405644" iyy="-0.0001034979" iyz="0.0001614047" izz="0.0001129895" />
    </inertial>
    <!-- Identified torque offset F0[5] = -4.732286 Nm (feed-forward term, add manually to your controller) -->
  </link>
  <joint name="wrist_rotate" type="revolute">
    <origin xyz="0.00000000 0.00000000 0.00000000" rpy="-1.57079633 -0.00000000 0.00000000" />
    <parent link="gripper_link" />
    <child link="ee_arm" />
    <axis xyz="0 0 1" />
    <limit lower="-3.141590" upper="3.141590" effort="4.100" velocity="3.141590" />
    <dynamics damping="0.00001235" friction="0.00000000" />
  </joint>
  <link name="ee_arm">
    <inertial>
      <origin xyz="0.32913015 0.00398655 0.12093974" rpy="0 0 0" />
      <mass value="0.00188218" />
      <inertia ixx="0.0000580448" ixy="0.0000125179" ixz="0.0001129016" iyy="-0.0002398271" iyz="-0.0001143496" izz="-0.0000801075" />
    </inertial>
    <!-- Identified torque offset F0[6] = 0.108992 Nm (feed-forward term, add manually to your controller) -->
  </link>
  <joint name="ee_arm" type="fixed">
    <origin xyz="0.13658000 0.0 0.0" rpy="0 0 0" />
    <parent link="ee_arm" />
    <child link="ee_link" />
  </joint>
  <link name="ee_link" />
</robot>