<?xml version="1.0" ?>
<robot name="viper300_sysid">
  <!-- Generated by phi_to_urdf.py on 2026-05-19 09:32:41 -->
  <link name="base_link">
    <inertial>
      <mass value="0.0" />
      <inertia ixx="0" ixy="0" ixz="0" iyy="0" iyz="0" izz="0" />
    </inertial>
  </link>
  <joint name="waist" type="revolute">
    <origin xyz="0.00000000 0.00000000 0.12675000" rpy="0.00000000 -0.00000000 0.00000000" />
    <parent link="base_link" />
    <child link="waist_link" />
    <axis xyz="0 0 1" />
    <limit lower="-3.141590" upper="3.141590" effort="4.100" velocity="3.141590" />
    <dynamics damping="0.14955191" friction="0.24590077" />
  </joint>
  <link name="waist_link">
    <inertial>
      <origin xyz="0.18422241 0.34123792 0.25892433" rpy="0 0 0" />
      <mass value="0.96563380" />
      <inertia ixx="0.0002111077" ixy="0.0000042103" ixz="0.0000266467" iyy="0.0001910892" iyz="-0.0000082452" izz="0.0002116649" />
    </inertial>
    <!-- Identified torque offset F0[1] = -0.042068 Nm (feed-forward term, add manually to your controller) -->
  </link>
  <joint name="shoulder" type="revolute">
    <origin xyz="0.00000000 -0.00000000 0.00000000" rpy="-1.57079633 -0.00000000 -1.37287599" />
    <parent link="waist_link" />
    <child link="upper_arm_link" />
    <axis xyz="0 0 1" />
    <limit lower="-1.876300" upper="1.989700" effort="10.600" velocity="2.610500" />
    <dynamics damping="0.09149630" friction="0.28998584" />
  </joint>
  <link name="upper_arm_link">
    <inertial>
      <origin xyz="-0.19564132 0.04763396 0.02962985" rpy="0 0 0" />
      <mass value="0.53159941" />
      <inertia ixx="0.0282223354" ixy="0.0030359407" ixz="-0.0044956327" iyy="0.0208983562" iyz="0.0124555315" izz="0.0097177420" />
    </inertial>
    <!-- Identified torque offset F0[2] = -0.205093 Nm (feed-forward term, add manually to your controller) -->
  </link>
  <joint name="elbow" type="revolute">
    <origin xyz="0.29996732 -0.06015719 0.00000000" rpy="0.00000000 -0.00000000 -0.19792034" />
    <parent link="upper_arm_link" />
    <child link="forearm_link" />
    <axis xyz="0 0 1" />
    <limit lower="-2.152100" upper="1.570800" effort="10.600" velocity="2.610500" />
    <dynamics damping="0.04757744" friction="0.45828118" />
  </joint>
  <link name="forearm_link">
    <inertial>
      <origin xyz="-0.43244926 0.03925550 -0.47164512" rpy="0 0 0" />
      <mass value="0.48272875" />
      <inertia ixx="0.0167611308" ixy="-0.0018595412" ixz="-0.0007414545" iyy="0.0177336118" iyz="-0.0004315567" izz="0.0135785256" />
    </inertial>
    <!-- Identified torque offset F0[3] = -0.757773 Nm (feed-forward term, add manually to your controller) -->
  </link>
  <joint name="forearm_roll" type="revolute">
    <origin xyz="0.00000000 0.00000000 0.30002000" rpy="-1.57079633 -0.00000000 0.00000000" />
    <parent link="forearm_link" />
    <child link="wrist_link" />
    <axis xyz="0 0 1" />
    <limit lower="-3.141590" upper="3.141590" effort="4.100" velocity="3.141590" />
    <dynamics damping="0.03256897" friction="0.03580219" />
  </joint>
  <link name="wrist_link">
    <inertial>
      <origin xyz="0.58221363 -0.11835413 -0.18696430" rpy="0 0 0" />
      <mass value="0.23882041" />
      <inertia ixx="0.0101851471" ixy="0.0011539677" ixz="-0.0000349548" iyy="0.0147157384" iyz="-0.0010815589" izz="0.0079988818" />
    </inertial>
    <!-- Identified torque offset F0[4] = 0.029741 Nm (feed-forward term, add manually to your controller) -->
  </link>
  <joint name="wrist_angle" type="revolute">
    <origin xyz="0.00000000 0.00000000 0.00000000" rpy="1.57079633 -0.00000000 0.00000000" />
    <parent link="wrist_link" />
    <child link="gripper_link" />
    <axis xyz="0 0 1" />
    <limit lower="-1.745300" upper="2.146800" effort="4.100" velocity="3.141590" />
    <dynamics damping="0.02756586" friction="0.07125923" />
  </joint>
  <link name="gripper_link">
    <inertial>
      <origin xyz="-0.43968184 0.10177587 -0.39561582" rpy="0 0 0" />
      <mass value="0.21807513" />
      <inertia ixx="0.0057841487" ixy="-0.0013064917" ixz="0.0002703453" iyy="0.0121837649" iyz="0.0000038155" izz="0.0107172536" />
    </inertial>
    <!-- Identified torque offset F0[5] = -0.024582 Nm (feed-forward term, add manually to your controller) -->
  </link>
  <joint name="wrist_rotate" type="revolute">
    <origin xyz="0.00000000 0.00000000 0.00000000" rpy="-1.57079633 -0.00000000 0.00000000" />
    <parent link="gripper_link" />
    <child link="ee_arm" />
    <axis xyz="0 0 1" />
    <limit lower="-3.141590" upper="3.141590" effort="4.100" velocity="3.141590" />
    <dynamics damping="0.01567070" friction="0.01702068" />
  </joint>
  <link name="ee_arm">
    <inertial>
      <origin xyz="0.24587472 0.21545882 0.31289943" rpy="0 0 0" />
      <mass value="0.08223456" />
      <inertia ixx="0.0171968699" ixy="-0.0025390826" ixz="-0.0022811513" iyy="0.0144060820" iyz="0.0008229710" izz="0.0097241799" />
    </inertial>
    <!-- Identified torque offset F0[6] = 0.008247 Nm (feed-forward term, add manually to your controller) -->
  </link>
  <joint name="ee_arm" type="fixed">
    <origin xyz="0.13658000 0.0 0.0" rpy="0 0 0" />
    <parent link="ee_arm" />
    <child link="ee_link" />
  </joint>
  <link name="ee_link" />
</robot>