<?xml version="1.0" ?>
<robot name="viper300_sysid">
  <!-- Generated by phi_to_urdf 1.0 | phi: outputs/npy/traj_run_20260518_143818__sysid_feasible-v1-4__cfg-640cb8ef.npy -->
  <link name="base_link">
    <inertial>
      <mass value="0.0" />
      <inertia ixx="0" ixy="0" ixz="0" iyy="0" iyz="0" izz="0" />
    </inertial>
  </link>
  <joint name="waist" type="revolute">
    <origin xyz="0.00000000 0.00000000 0.12675000" rpy="0.00000000 -0.00000000 0.00000000" />
    <parent link="base_link" />
    <child link="waist_link" />
    <axis xyz="0 0 1" />
    <limit lower="-3.141590" upper="3.141590" effort="4.100" velocity="3.141590" />
    <dynamics damping="0.00322929" friction="0.09199931" />
  </joint>
  <link name="waist_link">
    <inertial>
      <origin xyz="0.00000000 0.00000000 0.00000000" rpy="0 0 0" />
      <mass value="0.50001141" />
      <inertia ixx="0.0019950573" ixy="0.0000000000" ixz="0.0000000000" iyy="0.0019950453" iyz="0.0000000000" izz="0.0019901206" />
    </inertial>
    <!-- Identified torque offset F0[1] = -0.001389 Nm (feed-forward term, add manually to your controller) -->
  </link>
  <joint name="shoulder" type="revolute">
    <origin xyz="0.00000000 -0.00000000 0.00000000" rpy="-1.57079633 -0.00000000 -1.37287599" />
    <parent link="waist_link" />
    <child link="upper_arm_link" />
    <axis xyz="0 0 1" />
    <limit lower="-1.876300" upper="1.989700" effort="10.600" velocity="2.610500" />
    <dynamics damping="0.00000003" friction="0.43891729" />
  </joint>
  <link name="upper_arm_link">
    <inertial>
      <origin xyz="0.00000003 0.00005162 0.00000019" rpy="0 0 0" />
      <mass value="0.50002125" />
      <inertia ixx="0.0020240429" ixy="-0.0000006988" ixz="-0.0000000026" iyy="0.0020480859" iyz="-0.0000036921" izz="0.0020240118" />
    </inertial>
    <!-- Identified torque offset F0[2] = -0.872473 Nm (feed-forward term, add manually to your controller) -->
  </link>
  <joint name="elbow" type="revolute">
    <origin xyz="0.29996732 -0.06015719 0.00000000" rpy="0.00000000 -0.00000000 -0.19792034" />
    <parent link="upper_arm_link" />
    <child link="forearm_link" />
    <axis xyz="0 0 1" />
    <limit lower="-2.152100" upper="1.570800" effort="10.600" velocity="2.610500" />
    <dynamics damping="0.00000006" friction="0.58060420" />
  </joint>
  <link name="forearm_link">
    <inertial>
      <origin xyz="-0.15600136 0.00339746 -0.02412724" rpy="0 0 0" />
      <mass value="0.26336895" />
      <inertia ixx="0.0020827201" ixy="0.0000022124" ixz="0.0000046300" iyy="0.0022209609" iyz="0.0000014282" izz="0.0022555333" />
    </inertial>
    <!-- Identified torque offset F0[3] = -2.785865 Nm (feed-forward term, add manually to your controller) -->
  </link>
  <joint name="forearm_roll" type="revolute">
    <origin xyz="0.00000000 0.00000000 0.30002000" rpy="-1.57079633 -0.00000000 0.00000000" />
    <parent link="forearm_link" />
    <child link="wrist_link" />
    <axis xyz="0 0 1" />
    <limit lower="-3.141590" upper="3.141590" effort="4.100" velocity="3.141590" />
    <dynamics damping="0.00273679" friction="0.88757259" />
  </joint>
  <link name="wrist_link">
    <inertial>
      <origin xyz="-0.00238496 -0.00038769 0.00105421" rpy="0 0 0" />
      <mass value="0.02694847" />
      <inertia ixx="0.0019830913" ixy="0.0000007032" ixz="-0.0000002187" iyy="0.0019778628" iyz="0.0000013135" izz="0.0019830113" />
    </inertial>
    <!-- Identified torque offset F0[4] = 0.197537 Nm (feed-forward term, add manually to your controller) -->
  </link>
  <joint name="wrist_angle" type="revolute">
    <origin xyz="0.00000000 0.00000000 0.00000000" rpy="1.57079633 -0.00000000 0.00000000" />
    <parent link="wrist_link" />
    <child link="gripper_link" />
    <axis xyz="0 0 1" />
    <limit lower="-1.745300" upper="2.146800" effort="4.100" velocity="3.141590" />
    <dynamics damping="0.00001694" friction="0.13086242" />
  </joint>
  <link name="gripper_link">
    <inertial>
      <origin xyz="-0.00028791 0.00044840 -0.00019803" rpy="0 0 0" />
      <mass value="0.02694355" />
      <inertia ixx="0.0019728473" ixy="-0.0000000532" ixz="-0.0000001509" iyy="0.0019726768" iyz="-0.0000001344" izz="0.0019727973" />
    </inertial>
    <!-- Identified torque offset F0[5] = -0.155072 Nm (feed-forward term, add manually to your controller) -->
  </link>
  <joint name="wrist_rotate" type="revolute">
    <origin xyz="0.00000000 0.00000000 0.00000000" rpy="-1.57079633 -0.00000000 0.00000000" />
    <parent link="gripper_link" />
    <child link="ee_arm" />
    <axis xyz="0 0 1" />
    <limit lower="-3.141590" upper="3.141590" effort="4.100" velocity="3.141590" />
    <dynamics damping="0.00065031" friction="0.00000053" />
  </joint>
  <link name="ee_arm">
    <inertial>
      <origin xyz="0.00007606 0.00077684 0.00010554" rpy="0 0 0" />
      <mass value="0.02694365" />
      <inertia ixx="0.0019688328" ixy="-0.0000000026" ixz="-0.0000000058" iyy="0.0019688590" iyz="-0.0000000147" izz="0.0019688105" />
    </inertial>
    <!-- Identified torque offset F0[6] = -0.000552 Nm (feed-forward term, add manually to your controller) -->
  </link>
  <joint name="ee_arm" type="fixed">
    <origin xyz="0.13658000 0.0 0.0" rpy="0 0 0" />
    <parent link="ee_arm" />
    <child link="ee_link" />
  </joint>
  <link name="ee_link" />
</robot>