<?xml version="1.0" ?>
<robot name="viper300_sysid">
  <!-- Generated by phi_to_urdf 1.0 | phi: outputs/npy/traj_run_200hz_20260612_131613__sysid_feasible-v1-4__cfg-ce8e7059.npy -->
  <!-- Identified reflected motor inertia Ia [kg·m²]: waist=0.083329, shoulder=0.797737, elbow=0.155540, forearm_roll=0.000002, wrist_angle=0.039885, wrist_rotate=0.008776 (per-joint feed-forward term Ia·q̈ — add to your controller / pinocchio model.armature; a URDF cannot represent it) -->
  <link name="base_link">
    <inertial>
      <mass value="0.0" />
      <inertia ixx="0" ixy="0" ixz="0" iyy="0" iyz="0" izz="0" />
    </inertial>
  </link>
  <joint name="waist" type="revolute">
    <origin xyz="0.00000000 0.00000000 0.12675000" rpy="0.00000000 -0.00000000 0.00000000" />
    <parent link="base_link" />
    <child link="waist_link" />
    <axis xyz="0 0 1" />
    <limit lower="-3.141590" upper="3.141590" effort="4.100" velocity="3.141590" />
    <dynamics damping="0.03932346" friction="0.09121243" />
  </joint>
  <link name="waist_link">
    <inertial>
      <origin xyz="0.00000000 0.00000000 0.00000000" rpy="0 0 0" />
      <mass value="0.50003664" />
      <inertia ixx="0.0019999864" ixy="0.0000000000" ixz="0.0000000000" iyy="0.0019999743" iyz="0.0000000000" izz="0.0019999831" />
    </inertial>
    <!-- Identified torque offset F0[1] = -0.005410 Nm (feed-forward term, add manually to your controller) -->
  </link>
  <joint name="shoulder" type="revolute">
    <origin xyz="0.00000000 -0.00000000 0.00000000" rpy="-1.57079633 -0.00000000 -1.37287599" />
    <parent link="waist_link" />
    <child link="upper_arm_link" />
    <axis xyz="0 0 1" />
    <limit lower="-1.876300" upper="1.989700" effort="10.600" velocity="2.610500" />
    <dynamics damping="0.00000001" friction="0.54734040" />
  </joint>
  <link name="upper_arm_link">
    <inertial>
      <origin xyz="0.00000183 0.00005052 -0.00000107" rpy="0 0 0" />
      <mass value="0.50003623" />
      <inertia ixx="0.0019630429" ixy="-0.0000412014" ixz="0.0000008726" iyy="0.0019227066" iyz="0.0000212269" izz="0.0019642833" />
    </inertial>
    <!-- Identified torque offset F0[2] = -0.152290 Nm (feed-forward term, add manually to your controller) -->
  </link>
  <joint name="elbow" type="revolute">
    <origin xyz="0.29996732 -0.06015719 0.00000000" rpy="0.00000000 -0.00000000 -0.19792034" />
    <parent link="upper_arm_link" />
    <child link="forearm_link" />
    <axis xyz="0 0 1" />
    <limit lower="-2.152100" upper="1.570800" effort="10.600" velocity="2.610500" />
    <dynamics damping="0.00000291" friction="0.54567290" />
  </joint>
  <link name="forearm_link">
    <inertial>
      <origin xyz="0.01325085 0.01776986 -0.00274769" rpy="0 0 0" />
      <mass value="0.02824780" />
      <inertia ixx="0.0020767139" ixy="-0.0000125817" ixz="0.0000066900" iyy="0.0017822664" iyz="-0.0000011959" izz="0.0019382997" />
    </inertial>
    <!-- Identified torque offset F0[3] = -0.917016 Nm (feed-forward term, add manually to your controller) -->
  </link>
  <joint name="forearm_roll" type="revolute">
    <origin xyz="0.00000000 0.00000000 0.30002000" rpy="-1.57079633 -0.00000000 0.00000000" />
    <parent link="forearm_link" />
    <child link="wrist_link" />
    <axis xyz="0 0 1" />
    <limit lower="-3.141590" upper="3.141590" effort="4.100" velocity="3.141590" />
    <dynamics damping="0.53907266" friction="0.56021116" />
  </joint>
  <link name="wrist_link">
    <inertial>
      <origin xyz="0.01224868 -0.00041675 0.00506316" rpy="0 0 0" />
      <mass value="0.02432579" />
      <inertia ixx="0.0020813222" ixy="-0.0000129767" ixz="0.0000008480" iyy="0.0020554423" iyz="-0.0000036514" izz="0.0020361163" />
    </inertial>
    <!-- Identified torque offset F0[4] = 0.141470 Nm (feed-forward term, add manually to your controller) -->
  </link>
  <joint name="wrist_angle" type="revolute">
    <origin xyz="0.00000000 0.00000000 0.00000000" rpy="1.57079633 -0.00000000 0.00000000" />
    <parent link="wrist_link" />
    <child link="gripper_link" />
    <axis xyz="0 0 1" />
    <limit lower="-1.745300" upper="2.146800" effort="4.100" velocity="3.141590" />
    <dynamics damping="0.00000052" friction="0.11643827" />
  </joint>
  <link name="gripper_link">
    <inertial>
      <origin xyz="0.00092988 0.00042341 0.00625149" rpy="0 0 0" />
      <mass value="0.02424632" />
      <inertia ixx="0.0020273480" ixy="-0.0000007386" ixz="0.0000023827" iyy="0.0020255729" iyz="-0.0000025384" izz="0.0020128867" />
    </inertial>
    <!-- Identified torque offset F0[5] = -0.127416 Nm (feed-forward term, add manually to your controller) -->
  </link>
  <joint name="wrist_rotate" type="revolute">
    <origin xyz="0.00000000 0.00000000 0.00000000" rpy="-1.57079633 -0.00000000 0.00000000" />
    <parent link="gripper_link" />
    <child link="ee_arm" />
    <axis xyz="0 0 1" />
    <limit lower="-3.141590" upper="3.141590" effort="4.100" velocity="3.141590" />
    <dynamics damping="0.00201679" friction="0.00000077" />
  </joint>
  <link name="ee_arm">
    <inertial>
      <origin xyz="0.00024587 0.00061251 0.00046622" rpy="0 0 0" />
      <mass value="0.02422358" />
      <inertia ixx="0.0020023558" ixy="0.0000002664" ixz="0.0000006972" iyy="0.0020006119" iyz="0.0000006489" izz="0.0019993576" />
    </inertial>
    <!-- Identified torque offset F0[6] = -0.003775 Nm (feed-forward term, add manually to your controller) -->
  </link>
  <joint name="ee_arm" type="fixed">
    <origin xyz="0.13658000 0.0 0.0" rpy="0 0 0" />
    <parent link="ee_arm" />
    <child link="ee_link" />
  </joint>
  <link name="ee_link" />
</robot>