<?xml version="1.0" ?>
<robot name="viper300_sysid">
  <!-- Generated by phi_to_urdf 1.0 | phi: outputs/npy/traj_run_200hz_20260612_131613__sysid_feasible-v1-4__cfg-a0fa15f7.npy -->
  <!-- Identified reflected motor inertia Ia [kg·m²]: waist=0.083373, shoulder=0.798040, elbow=0.156930, forearm_roll=0.000001, wrist_angle=0.039895, wrist_rotate=0.008776 (per-joint feed-forward term Ia·q̈ — add to your controller / pinocchio model.armature; a URDF cannot represent it) -->
  <link name="base_link">
    <inertial>
      <mass value="0.0" />
      <inertia ixx="0" ixy="0" ixz="0" iyy="0" iyz="0" izz="0" />
    </inertial>
  </link>
  <joint name="waist" type="revolute">
    <origin xyz="0.00000000 0.00000000 0.12675000" rpy="0.00000000 -0.00000000 0.00000000" />
    <parent link="base_link" />
    <child link="waist_link" />
    <axis xyz="0 0 1" />
    <limit lower="-3.141590" upper="3.141590" effort="4.100" velocity="3.141590" />
    <dynamics damping="0.03935970" friction="0.09121294" />
  </joint>
  <link name="waist_link">
    <inertial>
      <origin xyz="0.00000000 0.00000000 0.00000000" rpy="0 0 0" />
      <mass value="0.50010696" />
      <inertia ixx="0.0020000509" ixy="0.0000000000" ixz="0.0000000000" iyy="0.0020000408" iyz="0.0000000000" izz="0.0019999271" />
    </inertial>
    <!-- Identified torque offset F0[1] = -0.005410 Nm (feed-forward term, add manually to your controller) -->
  </link>
  <joint name="shoulder" type="revolute">
    <origin xyz="0.00000000 -0.00000000 0.00000000" rpy="-1.57079633 -0.00000000 -1.37287599" />
    <parent link="waist_link" />
    <child link="upper_arm_link" />
    <axis xyz="0 0 1" />
    <limit lower="-1.876300" upper="1.989700" effort="10.600" velocity="2.610500" />
    <dynamics damping="0.00000001" friction="0.54679205" />
  </joint>
  <link name="upper_arm_link">
    <inertial>
      <origin xyz="0.00001536 0.00008685 -0.00000797" rpy="0 0 0" />
      <mass value="0.50011584" />
      <inertia ixx="0.0018905611" ixy="-0.0001861715" ixz="0.0000170897" iyy="0.0017052223" iyz="0.0000963819" izz="0.0019146889" />
    </inertial>
    <!-- Identified torque offset F0[2] = -0.197272 Nm (feed-forward term, add manually to your controller) -->
  </link>
  <joint name="elbow" type="revolute">
    <origin xyz="0.29996732 -0.06015719 0.00000000" rpy="0.00000000 -0.00000000 -0.19792034" />
    <parent link="upper_arm_link" />
    <child link="forearm_link" />
    <axis xyz="0 0 1" />
    <limit lower="-2.152100" upper="1.570800" effort="10.600" velocity="2.610500" />
    <dynamics damping="0.00000151" friction="0.54566753" />
  </joint>
  <link name="forearm_link">
    <inertial>
      <origin xyz="0.04554326 0.16487445 -0.01118247" rpy="0 0 0" />
      <mass value="0.01173658" />
      <inertia ixx="0.0028942256" ixy="-0.0000677935" ixz="0.0000164095" iyy="0.0013151919" iyz="-0.0000080169" izz="0.0025447985" />
    </inertial>
    <!-- Identified torque offset F0[3] = -0.882717 Nm (feed-forward term, add manually to your controller) -->
  </link>
  <joint name="forearm_roll" type="revolute">
    <origin xyz="0.00000000 0.00000000 0.30002000" rpy="-1.57079633 -0.00000000 0.00000000" />
    <parent link="forearm_link" />
    <child link="wrist_link" />
    <axis xyz="0 0 1" />
    <limit lower="-3.141590" upper="3.141590" effort="4.100" velocity="3.141590" />
    <dynamics damping="0.53912471" friction="0.56018531" />
  </joint>
  <link name="wrist_link">
    <inertial>
      <origin xyz="0.06209161 -0.00124015 0.03123480" rpy="0 0 0" />
      <mass value="0.00812562" />
      <inertia ixx="0.0024934053" ixy="-0.0000755410" ixz="0.0000040572" iyy="0.0023423393" iyz="-0.0000257660" izz="0.0022093773" />
    </inertial>
    <!-- Identified torque offset F0[4] = 0.141447 Nm (feed-forward term, add manually to your controller) -->
  </link>
  <joint name="wrist_angle" type="revolute">
    <origin xyz="0.00000000 0.00000000 0.00000000" rpy="1.57079633 -0.00000000 0.00000000" />
    <parent link="wrist_link" />
    <child link="gripper_link" />
    <axis xyz="0 0 1" />
    <limit lower="-1.745300" upper="2.146800" effort="4.100" velocity="3.141590" />
    <dynamics damping="0.00000032" friction="0.11643706" />
  </joint>
  <link name="gripper_link">
    <inertial>
      <origin xyz="0.00442428 0.00128518 0.03383144" rpy="0 0 0" />
      <mass value="0.00790217" />
      <inertia ixx="0.0021460552" ixy="-0.0000037482" ixz="0.0000131775" iyy="0.0021366708" iyz="-0.0000141593" izz="0.0020658461" />
    </inertial>
    <!-- Identified torque offset F0[5] = -0.127356 Nm (feed-forward term, add manually to your controller) -->
  </link>
  <joint name="wrist_rotate" type="revolute">
    <origin xyz="0.00000000 0.00000000 0.00000000" rpy="-1.57079633 -0.00000000 0.00000000" />
    <parent link="gripper_link" />
    <child link="ee_arm" />
    <axis xyz="0 0 1" />
    <limit lower="-3.141590" upper="3.141590" effort="4.100" velocity="3.141590" />
    <dynamics damping="0.00201484" friction="0.00000048" />
  </joint>
  <link name="ee_arm">
    <inertial>
      <origin xyz="0.00120989 0.00172004 0.00233413" rpy="0 0 0" />
      <mass value="0.00783732" />
      <inertia ixx="0.0020118827" ixy="0.0000013009" ixz="0.0000034886" iyy="0.0020031404" iyz="0.0000032678" izz="0.0019969133" />
    </inertial>
    <!-- Identified torque offset F0[6] = -0.003772 Nm (feed-forward term, add manually to your controller) -->
  </link>
  <joint name="ee_arm" type="fixed">
    <origin xyz="0.13658000 0.0 0.0" rpy="0 0 0" />
    <parent link="ee_arm" />
    <child link="ee_link" />
  </joint>
  <link name="ee_link" />
</robot>