<?xml version="1.0" ?>
<robot name="viper300_sysid">
  <!-- Generated by phi_to_urdf 1.0 | phi: outputs/npy/traj_run_200hz_20260612_131613__sysid_feasible-v1-4__cfg-3a02a6b0.npy -->
  <!-- Identified reflected motor inertia Ia [kg·m²]: waist=0.083931, shoulder=0.798536, elbow=0.154488, forearm_roll=0.000000, wrist_angle=0.039895, wrist_rotate=0.008779 (per-joint feed-forward term Ia·q̈ — add to your controller / pinocchio model.armature; a URDF cannot represent it) -->
  <link name="base_link">
    <inertial>
      <mass value="0.0" />
      <inertia ixx="0" ixy="0" ixz="0" iyy="0" iyz="0" izz="0" />
    </inertial>
  </link>
  <joint name="waist" type="revolute">
    <origin xyz="0.00000000 0.00000000 0.12675000" rpy="0.00000000 -0.00000000 0.00000000" />
    <parent link="base_link" />
    <child link="waist_link" />
    <axis xyz="0 0 1" />
    <limit lower="-3.141590" upper="3.141590" effort="4.100" velocity="3.141590" />
    <dynamics damping="0.03980562" friction="0.09061696" />
  </joint>
  <link name="waist_link">
    <inertial>
      <origin xyz="0.00000000 0.00000000 0.00000000" rpy="0 0 0" />
      <mass value="0.50006065" />
      <inertia ixx="0.0019999615" ixy="0.0000000000" ixz="0.0000000000" iyy="0.0019999516" iyz="0.0000000000" izz="0.0019999795" />
    </inertial>
    <!-- Identified torque offset F0[1] = -0.005482 Nm (feed-forward term, add manually to your controller) -->
  </link>
  <joint name="shoulder" type="revolute">
    <origin xyz="0.00000000 -0.00000000 0.00000000" rpy="-1.57079633 -0.00000000 -1.37287599" />
    <parent link="waist_link" />
    <child link="upper_arm_link" />
    <axis xyz="0 0 1" />
    <limit lower="-1.876300" upper="1.989700" effort="10.600" velocity="2.610500" />
    <dynamics damping="0.00000000" friction="0.54555037" />
  </joint>
  <link name="upper_arm_link">
    <inertial>
      <origin xyz="0.00015910 0.00030069 -0.00008307" rpy="0 0 0" />
      <mass value="0.50006296" />
      <inertia ixx="0.0042621461" ixy="-0.0018565135" ixz="0.0005129840" iyy="0.0022591934" iyz="0.0009650602" izz="0.0049823162" />
    </inertial>
    <!-- Identified torque offset F0[2] = -0.240201 Nm (feed-forward term, add manually to your controller) -->
  </link>
  <joint name="elbow" type="revolute">
    <origin xyz="0.29996732 -0.06015719 0.00000000" rpy="0.00000000 -0.00000000 -0.19792034" />
    <parent link="upper_arm_link" />
    <child link="forearm_link" />
    <axis xyz="0 0 1" />
    <limit lower="-2.152100" upper="1.570800" effort="10.600" velocity="2.610500" />
    <dynamics damping="0.00000061" friction="0.54557375" />
  </joint>
  <link name="forearm_link">
    <inertial>
      <origin xyz="0.15333305 1.88075345 -0.01263323" rpy="0 0 0" />
      <mass value="0.02420236" />
      <inertia ixx="0.0095493533" ixy="-0.0004424965" ixz="0.0000114309" iyy="0.0006836135" iyz="-0.0001010758" izz="0.0092215715" />
    </inertial>
    <!-- Identified torque offset F0[3] = -0.926918 Nm (feed-forward term, add manually to your controller) -->
  </link>
  <joint name="forearm_roll" type="revolute">
    <origin xyz="0.00000000 0.00000000 0.30002000" rpy="-1.57079633 -0.00000000 0.00000000" />
    <parent link="forearm_link" />
    <child link="wrist_link" />
    <axis xyz="0 0 1" />
    <limit lower="-3.141590" upper="3.141590" effort="4.100" velocity="3.141590" />
    <dynamics damping="0.53951863" friction="0.55987027" />
  </joint>
  <link name="wrist_link">
    <inertial>
      <origin xyz="0.25905855 -0.00389804 1.03685176" rpy="0 0 0" />
      <mass value="0.00256753" />
      <inertia ixx="0.0152901789" ixy="-0.0009417058" ixz="-0.0003753519" iyy="0.0131212486" iyz="-0.0022894044" izz="0.0046190042" />
    </inertial>
    <!-- Identified torque offset F0[4] = 0.141814 Nm (feed-forward term, add manually to your controller) -->
  </link>
  <joint name="wrist_angle" type="revolute">
    <origin xyz="0.00000000 0.00000000 0.00000000" rpy="1.57079633 -0.00000000 0.00000000" />
    <parent link="wrist_link" />
    <child link="gripper_link" />
    <axis xyz="0 0 1" />
    <limit lower="-1.745300" upper="2.146800" effort="4.100" velocity="3.141590" />
    <dynamics damping="0.00000005" friction="0.11642979" />
  </joint>
  <link name="gripper_link">
    <inertial>
      <origin xyz="0.00829059 0.00537722 0.28545027" rpy="0 0 0" />
      <mass value="0.00186540" />
      <inertia ixx="0.0031289064" ixy="-0.0000163805" ixz="0.0001225846" iyy="0.0030619992" iyz="-0.0001378761" izz="0.0023607019" />
    </inertial>
    <!-- Identified torque offset F0[5] = -0.127304 Nm (feed-forward term, add manually to your controller) -->
  </link>
  <joint name="wrist_rotate" type="revolute">
    <origin xyz="0.00000000 0.00000000 0.00000000" rpy="-1.57079633 -0.00000000 0.00000000" />
    <parent link="gripper_link" />
    <child link="ee_arm" />
    <axis xyz="0 0 1" />
    <limit lower="-3.141590" upper="3.141590" effort="4.100" velocity="3.141590" />
    <dynamics damping="0.00200264" friction="0.00000008" />
  </joint>
  <link name="ee_arm">
    <inertial>
      <origin xyz="0.00571368 0.00583653 0.01197388" rpy="0 0 0" />
      <mass value="0.00172640" />
      <inertia ixx="0.0020632029" ixy="0.0000061265" ixz="0.0000175941" iyy="0.0020202528" iyz="0.0000169847" izz="0.0019863787" />
    </inertial>
    <!-- Identified torque offset F0[6] = -0.003789 Nm (feed-forward term, add manually to your controller) -->
  </link>
  <joint name="ee_arm" type="fixed">
    <origin xyz="0.13658000 0.0 0.0" rpy="0 0 0" />
    <parent link="ee_arm" />
    <child link="ee_link" />
  </joint>
  <link name="ee_link" />
</robot>