<?xml version="1.0" ?>
<robot name="viper300_sysid">
  <!-- Generated by phi_to_urdf 1.0 | phi: outputs/npy/traj_run_200hz_20260612_131613__sysid_feasible-v1-4__cfg-f512651d.npy -->
  <!-- Identified reflected motor inertia Ia [kg·m²]: waist=0.083524, shoulder=0.798187, elbow=0.156365, forearm_roll=0.000000, wrist_angle=0.039897, wrist_rotate=0.008776 (per-joint feed-forward term Ia·q̈ — add to your controller / pinocchio model.armature; a URDF cannot represent it) -->
  <link name="base_link">
    <inertial>
      <mass value="0.0" />
      <inertia ixx="0" ixy="0" ixz="0" iyy="0" iyz="0" izz="0" />
    </inertial>
  </link>
  <joint name="waist" type="revolute">
    <origin xyz="0.00000000 0.00000000 0.12675000" rpy="0.00000000 -0.00000000 0.00000000" />
    <parent link="base_link" />
    <child link="waist_link" />
    <axis xyz="0 0 1" />
    <limit lower="-3.141590" upper="3.141590" effort="4.100" velocity="3.141590" />
    <dynamics damping="0.03947284" friction="0.09107623" />
  </joint>
  <link name="waist_link">
    <inertial>
      <origin xyz="0.00000000 0.00000000 0.00000000" rpy="0 0 0" />
      <mass value="0.50008513" />
      <inertia ixx="0.0020001107" ixy="0.0000000000" ixz="0.0000000000" iyy="0.0020001119" iyz="0.0000000000" izz="0.0020000140" />
    </inertial>
    <!-- Identified torque offset F0[1] = -0.005426 Nm (feed-forward term, add manually to your controller) -->
  </link>
  <joint name="shoulder" type="revolute">
    <origin xyz="0.00000000 -0.00000000 0.00000000" rpy="-1.57079633 -0.00000000 -1.37287599" />
    <parent link="waist_link" />
    <child link="upper_arm_link" />
    <axis xyz="0 0 1" />
    <limit lower="-1.876300" upper="1.989700" effort="10.600" velocity="2.610500" />
    <dynamics damping="0.00000000" friction="0.54644174" />
  </joint>
  <link name="upper_arm_link">
    <inertial>
      <origin xyz="0.00002611 0.00016216 -0.00002559" rpy="0 0 0" />
      <mass value="0.50009074" />
      <inertia ixx="0.0019417528" ixy="-0.0003644084" ixz="0.0000575131" iyy="0.0015707836" iyz="0.0001889086" izz="0.0020229501" />
    </inertial>
    <!-- Identified torque offset F0[2] = -0.211527 Nm (feed-forward term, add manually to your controller) -->
  </link>
  <joint name="elbow" type="revolute">
    <origin xyz="0.29996732 -0.06015719 0.00000000" rpy="0.00000000 -0.00000000 -0.19792034" />
    <parent link="upper_arm_link" />
    <child link="forearm_link" />
    <axis xyz="0 0 1" />
    <limit lower="-2.152100" upper="1.570800" effort="10.600" velocity="2.610500" />
    <dynamics damping="0.00000064" friction="0.54561745" />
  </joint>
  <link name="forearm_link">
    <inertial>
      <origin xyz="0.09341259 0.97834756 -0.01308196" rpy="0 0 0" />
      <mass value="0.01842648" />
      <inertia ixx="0.0081552637" ixy="-0.0003149323" ixz="0.0000167968" iyy="0.0010466451" iyz="-0.0000473425" izz="0.0077691201" />
    </inertial>
    <!-- Identified torque offset F0[3] = -0.893812 Nm (feed-forward term, add manually to your controller) -->
  </link>
  <joint name="forearm_roll" type="revolute">
    <origin xyz="0.00000000 0.00000000 0.30002000" rpy="-1.57079633 -0.00000000 0.00000000" />
    <parent link="forearm_link" />
    <child link="wrist_link" />
    <axis xyz="0 0 1" />
    <limit lower="-3.141590" upper="3.141590" effort="4.100" velocity="3.141590" />
    <dynamics damping="0.53922783" friction="0.56010961" />
  </joint>
  <link name="wrist_link">
    <inertial>
      <origin xyz="0.12547754 -0.00222445 0.08805004" rpy="0 0 0" />
      <mass value="0.00450674" />
      <inertia ixx="0.0033444728" ixy="-0.0001885331" ixz="0.0000052322" iyy="0.0029626475" iyz="-0.0000891215" izz="0.0025211294" />
    </inertial>
    <!-- Identified torque offset F0[4] = 0.141529 Nm (feed-forward term, add manually to your controller) -->
  </link>
  <joint name="wrist_angle" type="revolute">
    <origin xyz="0.00000000 0.00000000 0.00000000" rpy="1.57079633 -0.00000000 0.00000000" />
    <parent link="wrist_link" />
    <child link="gripper_link" />
    <axis xyz="0 0 1" />
    <limit lower="-1.745300" upper="2.146800" effort="4.100" velocity="3.141590" />
    <dynamics damping="0.00000011" friction="0.11643838" />
  </joint>
  <link name="gripper_link">
    <inertial>
      <origin xyz="0.00808321 0.00238020 0.07553142" rpy="0 0 0" />
      <mass value="0.00422555" />
      <inertia ixx="0.0023213203" ixy="-0.0000075592" ixz="0.0000302043" iyy="0.0023002084" iyz="-0.0000327825" izz="0.0021358922" />
    </inertial>
    <!-- Identified torque offset F0[5] = -0.127360 Nm (feed-forward term, add manually to your controller) -->
  </link>
  <joint name="wrist_rotate" type="revolute">
    <origin xyz="0.00000000 0.00000000 0.00000000" rpy="-1.57079633 -0.00000000 0.00000000" />
    <parent link="gripper_link" />
    <child link="ee_arm" />
    <axis xyz="0 0 1" />
    <limit lower="-3.141590" upper="3.141590" effort="4.100" velocity="3.141590" />
    <dynamics damping="0.00201078" friction="0.00000017" />
  </joint>
  <link name="ee_arm">
    <inertial>
      <origin xyz="0.00238700 0.00293411 0.00468998" rpy="0 0 0" />
      <mass value="0.00414417" />
      <inertia ixx="0.0020241595" ixy="0.0000025769" ixz="0.0000069892" iyy="0.0020066219" iyz="0.0000065985" izz="0.0019939763" />
    </inertial>
    <!-- Identified torque offset F0[6] = -0.003776 Nm (feed-forward term, add manually to your controller) -->
  </link>
  <joint name="ee_arm" type="fixed">
    <origin xyz="0.13658000 0.0 0.0" rpy="0 0 0" />
    <parent link="ee_arm" />
    <child link="ee_link" />
  </joint>
  <link name="ee_link" />
</robot>