<?xml version="1.0" ?>
<robot name="viper300_sysid">
  <!-- Generated by phi_to_urdf 1.1 | phi: outputs/npy/traj_run_20260518_143818__sysid_feasible-v1-5__cfg-9ef2c992.npy -->
  <link name="base_link">
    <inertial>
      <mass value="0.0" />
      <inertia ixx="0" ixy="0" ixz="0" iyy="0" iyz="0" izz="0" />
    </inertial>
  </link>
  <joint name="waist" type="revolute">
    <origin xyz="0.00000000 -0.00000000 0.12675000" rpy="0.00000000 -0.00000000 0.00000000" />
    <parent link="base_link" />
    <child link="waist_link" />
    <axis xyz="0 0 1" />
    <limit lower="-3.141590" upper="3.141590" effort="4.100" velocity="3.141590" />
    <dynamics damping="0.00456815" friction="0.09143748" />
  </joint>
  <link name="waist_link">
    <inertial>
      <origin xyz="0.00000000 0.00000000 0.00000000" rpy="0 0 0" />
      <mass value="0.50012358" />
      <inertia ixx="0.0019524132" ixy="0.0000000000" ixz="0.0000000000" iyy="0.0019521135" iyz="0.0000000000" izz="0.0019041499" />
    </inertial>
    <!-- Identified torque offset F0[1] = -0.001354 Nm (feed-forward term, add manually to your controller) -->
  </link>
  <joint name="shoulder" type="revolute">
    <origin xyz="0.00000000 0.00000000 -0.00000000" rpy="-1.57079633 -1.37287599 0.00000000" />
    <parent link="waist_link" />
    <child link="upper_arm_link" />
    <axis xyz="0 0 1" />
    <limit lower="-1.876300" upper="1.989700" effort="10.600" velocity="2.610500" />
    <dynamics damping="0.00000008" friction="0.44333810" />
  </joint>
  <link name="upper_arm_link">
    <inertial>
      <origin xyz="0.02953730 0.02453724 -0.00013788" rpy="0 0 0" />
      <mass value="10.14727758" />
      <inertia ixx="0.0018307101" ixy="0.0000343036" ixz="-0.0000006790" iyy="0.0017179019" iyz="0.0000055968" izz="0.0016450649" />
    </inertial>
    <!-- Identified torque offset F0[2] = 1.021007 Nm (feed-forward term, add manually to your controller) -->
  </link>
  <joint name="elbow" type="revolute">
    <origin xyz="0.30594000 -0.00000000 0.00000000" rpy="0.00000000 0.00000000 -0.19792034" />
    <parent link="upper_arm_link" />
    <child link="forearm_link" />
    <axis xyz="0 0 1" />
    <limit lower="-2.152100" upper="1.570800" effort="10.600" velocity="2.610500" />
    <dynamics damping="0.00000062" friction="0.57477093" />
  </joint>
  <link name="forearm_link">
    <inertial>
      <origin xyz="0.04045580 0.01152310 0.00033235" rpy="0 0 0" />
      <mass value="0.20214579" />
      <inertia ixx="0.0017394306" ixy="-0.0000040331" ixz="-0.0000025870" iyy="0.0022036476" iyz="-0.0000046110" izz="0.0020510413" />
    </inertial>
    <!-- Identified torque offset F0[3] = -1.301308 Nm (feed-forward term, add manually to your controller) -->
  </link>
  <joint name="forearm_roll" type="revolute">
    <origin xyz="0.00000000 0.30002000 -0.00000000" rpy="-1.57079633 0.00000000 -0.00000000" />
    <parent link="forearm_link" />
    <child link="wrist_link" />
    <axis xyz="0 0 1" />
    <limit lower="-3.141590" upper="3.141590" effort="4.100" velocity="3.141590" />
    <dynamics damping="0.05656067" friction="0.85638707" />
  </joint>
  <link name="wrist_link">
    <inertial>
      <origin xyz="-0.02905869 -0.01183711 -0.05075777" rpy="0 0 0" />
      <mass value="0.05875908" />
      <inertia ixx="0.0016687604" ixy="-0.0000019532" ixz="-0.0000022046" iyy="0.0017906396" iyz="-0.0000033215" izz="0.0018726341" />
    </inertial>
    <!-- Identified torque offset F0[4] = 0.188315 Nm (feed-forward term, add manually to your controller) -->
  </link>
  <joint name="wrist_angle" type="revolute">
    <origin xyz="0.00000000 -0.00000000 0.00000000" rpy="1.57079633 -0.00000000 0.00000000" />
    <parent link="wrist_link" />
    <child link="gripper_link" />
    <axis xyz="0 0 1" />
    <limit lower="-1.745300" upper="2.146800" effort="4.100" velocity="3.141590" />
    <dynamics damping="0.01145504" friction="0.11605819" />
  </joint>
  <link name="gripper_link">
    <inertial>
      <origin xyz="0.00346265 0.01158447 0.01155998" rpy="0 0 0" />
      <mass value="0.04774400" />
      <inertia ixx="0.0017900674" ixy="0.0000007847" ixz="-0.0000000825" iyy="0.0018018508" iyz="-0.0000001758" izz="0.0018408351" />
    </inertial>
    <!-- Identified torque offset F0[5] = -0.114519 Nm (feed-forward term, add manually to your controller) -->
  </link>
  <joint name="wrist_rotate" type="revolute">
    <origin xyz="0.00000000 0.00000000 -0.00000000" rpy="-1.57079633 0.00000000 -0.00000000" />
    <parent link="gripper_link" />
    <child link="ee_arm" />
    <axis xyz="0 0 1" />
    <limit lower="-3.141590" upper="3.141590" effort="4.100" velocity="3.141590" />
    <dynamics damping="0.00137034" friction="0.00000138" />
  </joint>
  <link name="ee_arm">
    <inertial>
      <origin xyz="0.00070657 0.00064792 0.01156662" rpy="0 0 0" />
      <mass value="0.04737155" />
      <inertia ixx="0.0018229088" ixy="-0.0000000032" ixz="0.0000000128" iyy="0.0019065209" iyz="0.0000000280" izz="0.0019003880" />
    </inertial>
    <!-- Identified torque offset F0[6] = -0.000842 Nm (feed-forward term, add manually to your controller) -->
  </link>
  <joint name="ee_arm" type="fixed">
    <origin xyz="0.13658000 0.0 0.0" rpy="0 0 0" />
    <parent link="ee_arm" />
    <child link="ee_link" />
  </joint>
  <link name="ee_link" />
</robot>