<?xml version="1.0" ?>
<robot name="viper300_sysid">
  <!-- Generated by phi_to_urdf 1.0 | phi: outputs/npy/traj_run_20260518_143818__sysid_feasible-v1-4__cfg-a5e08760.npy -->
  <link name="base_link">
    <inertial>
      <mass value="0.0" />
      <inertia ixx="0" ixy="0" ixz="0" iyy="0" iyz="0" izz="0" />
    </inertial>
  </link>
  <joint name="waist" type="revolute">
    <origin xyz="0.00000000 0.00000000 0.12675000" rpy="0.00000000 -0.00000000 0.00000000" />
    <parent link="base_link" />
    <child link="waist_link" />
    <axis xyz="0 0 1" />
    <limit lower="-3.141590" upper="3.141590" effort="4.100" velocity="3.141590" />
    <dynamics damping="0.01195219" friction="0.08678321" />
  </joint>
  <link name="waist_link">
    <inertial>
      <origin xyz="0.00000000 0.00000000 0.00000000" rpy="0 0 0" />
      <mass value="0.50002758" />
      <inertia ixx="0.0019949474" ixy="0.0000000000" ixz="0.0000000000" iyy="0.0019949403" iyz="0.0000000000" izz="0.0019898127" />
    </inertial>
    <!-- Identified torque offset F0[1] = -0.002171 Nm (feed-forward term, add manually to your controller) -->
  </link>
  <joint name="shoulder" type="revolute">
    <origin xyz="0.00000000 -0.00000000 0.00000000" rpy="-1.57079633 -0.00000000 -1.37287599" />
    <parent link="waist_link" />
    <child link="upper_arm_link" />
    <axis xyz="0 0 1" />
    <limit lower="-1.876300" upper="1.989700" effort="10.600" velocity="2.610500" />
    <dynamics damping="0.00000002" friction="0.43959599" />
  </joint>
  <link name="upper_arm_link">
    <inertial>
      <origin xyz="0.00000002 0.00005235 0.00000015" rpy="0 0 0" />
      <mass value="0.50002913" />
      <inertia ixx="0.0020153459" ixy="-0.0000002942" ixz="-0.0000000009" iyy="0.0020306924" iyz="-0.0000029316" izz="0.0020153389" />
    </inertial>
    <!-- Identified torque offset F0[2] = -0.855971 Nm (feed-forward term, add manually to your controller) -->
  </link>
  <joint name="elbow" type="revolute">
    <origin xyz="0.29996732 -0.06015719 0.00000000" rpy="0.00000000 -0.00000000 -0.19792034" />
    <parent link="upper_arm_link" />
    <child link="forearm_link" />
    <axis xyz="0 0 1" />
    <limit lower="-2.152100" upper="1.570800" effort="10.600" velocity="2.610500" />
    <dynamics damping="0.00000002" friction="0.58941681" />
  </joint>
  <link name="forearm_link">
    <inertial>
      <origin xyz="-0.14503636 0.00221768 -0.02245269" rpy="0 0 0" />
      <mass value="0.23089783" />
      <inertia ixx="0.0020702115" ixy="0.0000011545" ixz="0.0000049753" iyy="0.0021982320" iyz="0.0000029707" izz="0.0022376891" />
    </inertial>
    <!-- Identified torque offset F0[3] = -2.687555 Nm (feed-forward term, add manually to your controller) -->
  </link>
  <joint name="forearm_roll" type="revolute">
    <origin xyz="0.00000000 0.00000000 0.30002000" rpy="-1.57079633 -0.00000000 0.00000000" />
    <parent link="forearm_link" />
    <child link="wrist_link" />
    <axis xyz="0 0 1" />
    <limit lower="-3.141590" upper="3.141590" effort="4.100" velocity="3.141590" />
    <dynamics damping="0.00000066" friction="0.88456051" />
  </joint>
  <link name="wrist_link">
    <inertial>
      <origin xyz="-0.00384909 -0.00035592 0.00064909" rpy="0 0 0" />
      <mass value="0.02865359" />
      <inertia ixx="0.0019806672" ixy="0.0000009727" ixz="-0.0000000492" iyy="0.0019728964" iyz="0.0000019827" izz="0.0019813897" />
    </inertial>
    <!-- Identified torque offset F0[4] = 0.198189 Nm (feed-forward term, add manually to your controller) -->
  </link>
  <joint name="wrist_angle" type="revolute">
    <origin xyz="0.00000000 0.00000000 0.00000000" rpy="1.57079633 -0.00000000 0.00000000" />
    <parent link="wrist_link" />
    <child link="gripper_link" />
    <axis xyz="0 0 1" />
    <limit lower="-1.745300" upper="2.146800" effort="4.100" velocity="3.141590" />
    <dynamics damping="0.00217650" friction="0.12948645" />
  </joint>
  <link name="gripper_link">
    <inertial>
      <origin xyz="-0.00060184 0.00036962 -0.00085686" rpy="0 0 0" />
      <mass value="0.02864183" />
      <inertia ixx="0.0019761168" ixy="-0.0000000394" ixz="-0.0000001772" iyy="0.0019759208" iyz="-0.0000001268" izz="0.0019749034" />
    </inertial>
    <!-- Identified torque offset F0[5] = -0.155949 Nm (feed-forward term, add manually to your controller) -->
  </link>
  <joint name="wrist_rotate" type="revolute">
    <origin xyz="0.00000000 0.00000000 0.00000000" rpy="-1.57079633 -0.00000000 0.00000000" />
    <parent link="gripper_link" />
    <child link="ee_arm" />
    <axis xyz="0 0 1" />
    <limit lower="-3.141590" upper="3.141590" effort="4.100" velocity="3.141590" />
    <dynamics damping="0.00089982" friction="0.00000021" />
  </joint>
  <link name="ee_arm">
    <inertial>
      <origin xyz="0.00008628 0.00054353 0.00018868" rpy="0 0 0" />
      <mass value="0.02864107" />
      <inertia ixx="0.0019692075" ixy="-0.0000000045" ixz="0.0000000064" iyy="0.0019692564" iyz="-0.0000000061" izz="0.0019690633" />
    </inertial>
    <!-- Identified torque offset F0[6] = -0.000536 Nm (feed-forward term, add manually to your controller) -->
  </link>
  <joint name="ee_arm" type="fixed">
    <origin xyz="0.13658000 0.0 0.0" rpy="0 0 0" />
    <parent link="ee_arm" />
    <child link="ee_link" />
  </joint>
  <link name="ee_link" />
</robot>