<?xml version="1.0" ?>
<robot name="viper300_sysid">
  <!-- Generated by phi_to_urdf 1.0 | phi: outputs/npy/traj_run_200hz_20260612_131613__sysid_feasible-v1-4__cfg-759357cd.npy -->
  <!-- Identified reflected motor inertia Ia [kg·m²]: waist=0.083354, shoulder=0.797940, elbow=0.156503, forearm_roll=0.000002, wrist_angle=0.039892, wrist_rotate=0.008776 (per-joint feed-forward term Ia·q̈ — add to your controller / pinocchio model.armature; a URDF cannot represent it) -->
  <link name="base_link">
    <inertial>
      <mass value="0.0" />
      <inertia ixx="0" ixy="0" ixz="0" iyy="0" iyz="0" izz="0" />
    </inertial>
  </link>
  <joint name="waist" type="revolute">
    <origin xyz="0.00000000 0.00000000 0.12675000" rpy="0.00000000 -0.00000000 0.00000000" />
    <parent link="base_link" />
    <child link="waist_link" />
    <axis xyz="0 0 1" />
    <limit lower="-3.141590" upper="3.141590" effort="4.100" velocity="3.141590" />
    <dynamics damping="0.03934418" friction="0.09121674" />
  </joint>
  <link name="waist_link">
    <inertial>
      <origin xyz="0.00000000 0.00000000 0.00000000" rpy="0 0 0" />
      <mass value="0.50013424" />
      <inertia ixx="0.0019997813" ixy="0.0000000000" ixz="0.0000000000" iyy="0.0019997846" iyz="0.0000000000" izz="0.0019997867" />
    </inertial>
    <!-- Identified torque offset F0[1] = -0.005409 Nm (feed-forward term, add manually to your controller) -->
  </link>
  <joint name="shoulder" type="revolute">
    <origin xyz="0.00000000 -0.00000000 0.00000000" rpy="-1.57079633 -0.00000000 -1.37287599" />
    <parent link="waist_link" />
    <child link="upper_arm_link" />
    <axis xyz="0 0 1" />
    <limit lower="-1.876300" upper="1.989700" effort="10.600" velocity="2.610500" />
    <dynamics damping="0.00000001" friction="0.54697434" />
  </joint>
  <link name="upper_arm_link">
    <inertial>
      <origin xyz="0.00001107 0.00010638 -0.00000533" rpy="0 0 0" />
      <mass value="0.50013553" />
      <inertia ixx="0.0019230219" ixy="-0.0000981059" ixz="0.0000049120" iyy="0.0018266470" iyz="0.0000507281" izz="0.0019299831" />
    </inertial>
    <!-- Identified torque offset F0[2] = -0.182684 Nm (feed-forward term, add manually to your controller) -->
  </link>
  <joint name="elbow" type="revolute">
    <origin xyz="0.29996732 -0.06015719 0.00000000" rpy="0.00000000 -0.00000000 -0.19792034" />
    <parent link="upper_arm_link" />
    <child link="forearm_link" />
    <axis xyz="0 0 1" />
    <limit lower="-2.152100" upper="1.570800" effort="10.600" velocity="2.610500" />
    <dynamics damping="0.00000212" friction="0.54566989" />
  </joint>
  <link name="forearm_link">
    <inertial>
      <origin xyz="0.02784569 0.05403996 -0.00627780" rpy="0 0 0" />
      <mass value="0.01674952" />
      <inertia ixx="0.0022577572" ixy="-0.0000300180" ixz="0.0000122809" iyy="0.0015569720" iyz="-0.0000031299" izz="0.0019996450" />
    </inertial>
    <!-- Identified torque offset F0[3] = -0.893280 Nm (feed-forward term, add manually to your controller) -->
  </link>
  <joint name="forearm_roll" type="revolute">
    <origin xyz="0.00000000 0.00000000 0.30002000" rpy="-1.57079633 -0.00000000 0.00000000" />
    <parent link="forearm_link" />
    <child link="wrist_link" />
    <axis xyz="0 0 1" />
    <limit lower="-3.141590" upper="3.141590" effort="4.100" velocity="3.141590" />
    <dynamics damping="0.53910433" friction="0.56019636" />
  </joint>
  <link name="wrist_link">
    <inertial>
      <origin xyz="0.03077639 -0.00075832 0.01362439" rpy="0 0 0" />
      <mass value="0.01333736" />
      <inertia ixx="0.0022174340" ixy="-0.0000342631" ixz="0.0000021082" iyy="0.0021490797" iyz="-0.0000103076" izz="0.0020950234" />
    </inertial>
    <!-- Identified torque offset F0[4] = 0.141451 Nm (feed-forward term, add manually to your controller) -->
  </link>
  <joint name="wrist_angle" type="revolute">
    <origin xyz="0.00000000 0.00000000 0.00000000" rpy="1.57079633 -0.00000000 0.00000000" />
    <parent link="wrist_link" />
    <child link="gripper_link" />
    <axis xyz="0 0 1" />
    <limit lower="-1.745300" upper="2.146800" effort="4.100" velocity="3.141590" />
    <dynamics damping="0.00000041" friction="0.11643744" />
  </joint>
  <link name="gripper_link">
    <inertial>
      <origin xyz="0.00228586 0.00077399 0.01608244" rpy="0 0 0" />
      <mass value="0.01318766" />
      <inertia ixx="0.0020697859" ixy="-0.0000018565" ixz="0.0000061802" iyy="0.0020652907" iyz="-0.0000066071" izz="0.0020322715" />
    </inertial>
    <!-- Identified torque offset F0[5] = -0.127375 Nm (feed-forward term, add manually to your controller) -->
  </link>
  <joint name="wrist_rotate" type="revolute">
    <origin xyz="0.00000000 0.00000000 0.00000000" rpy="-1.57079633 -0.00000000 0.00000000" />
    <parent link="gripper_link" />
    <child link="ee_arm" />
    <axis xyz="0 0 1" />
    <limit lower="-3.141590" upper="3.141590" effort="4.100" velocity="3.141590" />
    <dynamics damping="0.00201575" friction="0.00000064" />
  </joint>
  <link name="ee_arm">
    <inertial>
      <origin xyz="0.00061035 0.00079363 0.00116571" rpy="0 0 0" />
      <mass value="0.01314433" />
      <inertia ixx="0.0020056873" ixy="0.0000006552" ixz="0.0000017432" iyy="0.0020013365" iyz="0.0000016262" izz="0.0019982095" />
    </inertial>
    <!-- Identified torque offset F0[6] = -0.003772 Nm (feed-forward term, add manually to your controller) -->
  </link>
  <joint name="ee_arm" type="fixed">
    <origin xyz="0.13658000 0.0 0.0" rpy="0 0 0" />
    <parent link="ee_arm" />
    <child link="ee_link" />
  </joint>
  <link name="ee_link" />
</robot>