<?xml version="1.0" ?>
<robot name="viper300_sysid">
  <!-- Generated by phi_to_urdf 1.0 | phi: outputs/traj_run_20260518_143818/traj_run_20260518_143818__sysid_feasible-v1-2__cfg-5d6e6cae.npy -->
  <link name="base_link">
    <inertial>
      <mass value="0.0" />
      <inertia ixx="0" ixy="0" ixz="0" iyy="0" iyz="0" izz="0" />
    </inertial>
  </link>
  <joint name="waist" type="revolute">
    <origin xyz="0.00000000 0.00000000 0.12675000" rpy="0.00000000 -0.00000000 0.00000000" />
    <parent link="base_link" />
    <child link="waist_link" />
    <axis xyz="0 0 1" />
    <limit lower="-3.141590" upper="3.141590" effort="4.100" velocity="3.141590" />
    <dynamics damping="0.29164082" friction="0.04402078" />
  </joint>
  <link name="waist_link">
    <inertial>
      <origin xyz="0.00708471 0.04961436 0.05060131" rpy="0 0 0" />
      <mass value="0.59718382" />
      <inertia ixx="0.0844669877" ixy="-0.0200848992" ixz="-0.0149426172" iyy="0.0931636682" iyz="0.0103995132" izz="0.0509002739" />
    </inertial>
    <!-- Identified torque offset F0[1] = -1.185175 Nm (feed-forward term, add manually to your controller) -->
  </link>
  <joint name="shoulder" type="revolute">
    <origin xyz="0.00000000 -0.00000000 0.00000000" rpy="-1.57079633 -0.00000000 -1.37287599" />
    <parent link="waist_link" />
    <child link="upper_arm_link" />
    <axis xyz="0 0 1" />
    <limit lower="-1.876300" upper="1.989700" effort="10.600" velocity="2.610500" />
    <dynamics damping="0.75544863" friction="0.62125047" />
  </joint>
  <link name="upper_arm_link">
    <inertial>
      <origin xyz="0.00174487 0.00422651 0.06153223" rpy="0 0 0" />
      <mass value="0.68685398" />
      <inertia ixx="0.0725346172" ixy="0.0147242481" ixz="0.0148336564" iyy="0.0689410913" iyz="-0.0183189723" izz="0.0632276970" />
    </inertial>
    <!-- Identified torque offset F0[2] = 2.792351 Nm (feed-forward term, add manually to your controller) -->
  </link>
  <joint name="elbow" type="revolute">
    <origin xyz="0.29996732 -0.06015719 0.00000000" rpy="0.00000000 -0.00000000 -0.19792034" />
    <parent link="upper_arm_link" />
    <child link="forearm_link" />
    <axis xyz="0 0 1" />
    <limit lower="-2.152100" upper="1.570800" effort="10.600" velocity="2.610500" />
    <dynamics damping="0.02296636" friction="0.90117050" />
  </joint>
  <link name="forearm_link">
    <inertial>
      <origin xyz="0.20171641 0.00257539 -0.24154112" rpy="0 0 0" />
      <mass value="0.59326291" />
      <inertia ixx="0.0584546743" ixy="-0.0114292528" ixz="0.0288367198" iyy="0.0702504278" iyz="0.0102307598" izz="0.0435850403" />
    </inertial>
    <!-- Identified torque offset F0[3] = 1.174027 Nm (feed-forward term, add manually to your controller) -->
  </link>
  <joint name="forearm_roll" type="revolute">
    <origin xyz="0.00000000 0.00000000 0.30002000" rpy="-1.57079633 -0.00000000 0.00000000" />
    <parent link="forearm_link" />
    <child link="wrist_link" />
    <axis xyz="0 0 1" />
    <limit lower="-3.141590" upper="3.141590" effort="4.100" velocity="3.141590" />
    <dynamics damping="0.29972495" friction="0.35927018" />
  </joint>
  <link name="wrist_link">
    <inertial>
      <origin xyz="0.24450673 -0.00002942 -0.13515658" rpy="0 0 0" />
      <mass value="0.37526289" />
      <inertia ixx="0.0665272442" ixy="0.0048318084" ixz="0.0012309721" iyy="0.0343425750" iyz="0.0128264913" izz="0.0607417428" />
    </inertial>
    <!-- Identified torque offset F0[4] = -0.868423 Nm (feed-forward term, add manually to your controller) -->
  </link>
  <joint name="wrist_angle" type="revolute">
    <origin xyz="0.00000000 0.00000000 0.00000000" rpy="1.57079633 -0.00000000 0.00000000" />
    <parent link="wrist_link" />
    <child link="gripper_link" />
    <axis xyz="0 0 1" />
    <limit lower="-1.745300" upper="2.146800" effort="4.100" velocity="3.141590" />
    <dynamics damping="0.03618339" friction="0.61045252" />
  </joint>
  <link name="gripper_link">
    <inertial>
      <origin xyz="0.23046055 0.00039541 -0.40399722" rpy="0 0 0" />
      <mass value="0.25340706" />
      <inertia ixx="0.0279749057" ixy="0.0289779866" ixz="-0.0092552353" iyy="0.0619357379" iyz="0.0050654262" izz="0.0722037860" />
    </inertial>
    <!-- Identified torque offset F0[5] = -0.446213 Nm (feed-forward term, add manually to your controller) -->
  </link>
  <joint name="wrist_rotate" type="revolute">
    <origin xyz="0.00000000 0.00000000 0.00000000" rpy="-1.57079633 -0.00000000 0.00000000" />
    <parent link="gripper_link" />
    <child link="ee_arm" />
    <axis xyz="0 0 1" />
    <limit lower="-3.141590" upper="3.141590" effort="4.100" velocity="3.141590" />
    <dynamics damping="0.31413416" friction="0.36029094" />
  </joint>
  <link name="ee_arm">
    <inertial>
      <origin xyz="-0.17785734 0.26751193 0.16732745" rpy="0 0 0" />
      <mass value="0.16359514" />
      <inertia ixx="0.0524163131" ixy="-0.0008829003" ixz="0.0087837144" iyy="0.0847883828" iyz="0.0018464697" izz="0.0777337474" />
    </inertial>
    <!-- Identified torque offset F0[6] = -0.141705 Nm (feed-forward term, add manually to your controller) -->
  </link>
  <joint name="ee_arm" type="fixed">
    <origin xyz="0.13658000 0.0 0.0" rpy="0 0 0" />
    <parent link="ee_arm" />
    <child link="ee_link" />
  </joint>
  <link name="ee_link" />
</robot>