<?xml version="1.0" ?>
<robot name="viper300_sysid">
  <!-- Generated by phi_to_urdf 1.0 | phi: outputs/npy/traj_run_200hz_20260612_131613__sysid_feasible-v1-4__cfg-b6ab472b.npy -->
  <link name="base_link">
    <inertial>
      <mass value="0.0" />
      <inertia ixx="0" ixy="0" ixz="0" iyy="0" iyz="0" izz="0" />
    </inertial>
  </link>
  <joint name="waist" type="revolute">
    <origin xyz="0.00000000 0.00000000 0.12675000" rpy="0.00000000 -0.00000000 0.00000000" />
    <parent link="base_link" />
    <child link="waist_link" />
    <axis xyz="0 0 1" />
    <limit lower="-3.141590" upper="3.141590" effort="4.100" velocity="3.141590" />
    <dynamics damping="0.05963578" friction="0.08153394" />
  </joint>
  <link name="waist_link">
    <inertial>
      <origin xyz="0.00000000 0.00000000 0.00000000" rpy="0 0 0" />
      <mass value="0.50024204" />
      <inertia ixx="0.0021959631" ixy="0.0000000000" ixz="0.0000000000" iyy="0.0021959269" iyz="0.0000000000" izz="0.0023910172" />
    </inertial>
    <!-- Identified torque offset F0[1] = -0.006586 Nm (feed-forward term, add manually to your controller) -->
  </link>
  <joint name="shoulder" type="revolute">
    <origin xyz="0.00000000 -0.00000000 0.00000000" rpy="-1.57079633 -0.00000000 -1.37287599" />
    <parent link="waist_link" />
    <child link="upper_arm_link" />
    <axis xyz="0 0 1" />
    <limit lower="-1.876300" upper="1.989700" effort="10.600" velocity="2.610500" />
    <dynamics damping="0.00000007" friction="0.72676467" />
  </joint>
  <link name="upper_arm_link">
    <inertial>
      <origin xyz="0.00016207 0.00023394 0.00013097" rpy="0 0 0" />
      <mass value="0.50024596" />
      <inertia ixx="0.0042767922" ixy="-0.0014615384" ixz="-0.0008178205" iyy="0.0046613609" iyz="-0.0011854552" izz="0.0046216693" />
    </inertial>
    <!-- Identified torque offset F0[2] = 0.227615 Nm (feed-forward term, add manually to your controller) -->
  </link>
  <joint name="elbow" type="revolute">
    <origin xyz="0.29996732 -0.06015719 0.00000000" rpy="0.00000000 -0.00000000 -0.19792034" />
    <parent link="upper_arm_link" />
    <child link="forearm_link" />
    <axis xyz="0 0 1" />
    <limit lower="-2.152100" upper="1.570800" effort="10.600" velocity="2.610500" />
    <dynamics damping="0.00000047" friction="0.55962902" />
  </joint>
  <link name="forearm_link">
    <inertial>
      <origin xyz="0.05851306 0.32905905 -0.03972492" rpy="0 0 0" />
      <mass value="0.05656403" />
      <inertia ixx="0.0110043514" ixy="-0.0004087499" ixz="0.0000255616" iyy="0.0021189460" iyz="0.0000512122" izz="0.0101311266" />
    </inertial>
    <!-- Identified torque offset F0[3] = -0.886274 Nm (feed-forward term, add manually to your controller) -->
  </link>
  <joint name="forearm_roll" type="revolute">
    <origin xyz="0.00000000 0.00000000 0.30002000" rpy="-1.57079633 -0.00000000 0.00000000" />
    <parent link="forearm_link" />
    <child link="wrist_link" />
    <axis xyz="0 0 1" />
    <limit lower="-3.141590" upper="3.141590" effort="4.100" velocity="3.141590" />
    <dynamics damping="0.54250199" friction="0.55860668" />
  </joint>
  <link name="wrist_link">
    <inertial>
      <origin xyz="0.05339648 -0.00015046 0.01570387" rpy="0 0 0" />
      <mass value="0.06739135" />
      <inertia ixx="0.0024402878" ixy="-0.0000646312" ixz="0.0000100489" iyy="0.0022392567" iyz="0.0000009346" izz="0.0021565033" />
    </inertial>
    <!-- Identified torque offset F0[4] = 0.148774 Nm (feed-forward term, add manually to your controller) -->
  </link>
  <joint name="wrist_angle" type="revolute">
    <origin xyz="0.00000000 0.00000000 0.00000000" rpy="1.57079633 -0.00000000 0.00000000" />
    <parent link="wrist_link" />
    <child link="gripper_link" />
    <axis xyz="0 0 1" />
    <limit lower="-1.745300" upper="2.146800" effort="4.100" velocity="3.141590" />
    <dynamics damping="0.00165529" friction="0.11255095" />
  </joint>
  <link name="gripper_link">
    <inertial>
      <origin xyz="0.00383609 0.00017458 0.03388752" rpy="0 0 0" />
      <mass value="0.05905541" />
      <inertia ixx="0.0021422622" ixy="0.0000025795" ixz="0.0000222131" iyy="0.0021441570" iyz="0.0000021511" izz="0.0020403145" />
    </inertial>
    <!-- Identified torque offset F0[5] = -0.122987 Nm (feed-forward term, add manually to your controller) -->
  </link>
  <joint name="wrist_rotate" type="revolute">
    <origin xyz="0.00000000 0.00000000 0.00000000" rpy="-1.57079633 -0.00000000 0.00000000" />
    <parent link="gripper_link" />
    <child link="ee_arm" />
    <axis xyz="0 0 1" />
    <limit lower="-3.141590" upper="3.141590" effort="4.100" velocity="3.141590" />
    <dynamics damping="0.00549266" friction="0.00000091" />
  </joint>
  <link name="ee_arm">
    <inertial>
      <origin xyz="0.00082288 0.00019035 0.00169563" rpy="0 0 0" />
      <mass value="0.05564222" />
      <inertia ixx="0.0020315233" ixy="-0.0000001213" ixz="0.0000010294" iyy="0.0020269859" iyz="0.0000017160" izz="0.0020130460" />
    </inertial>
    <!-- Identified torque offset F0[6] = -0.002442 Nm (feed-forward term, add manually to your controller) -->
  </link>
  <joint name="ee_arm" type="fixed">
    <origin xyz="0.13658000 0.0 0.0" rpy="0 0 0" />
    <parent link="ee_arm" />
    <child link="ee_link" />
  </joint>
  <link name="ee_link" />
</robot>