<?xml version="1.0" ?>
<robot name="viper300_sysid">
  <!-- Generated by phi_to_urdf 1.0 | phi: outputs/npy/traj_run_200hz_20260612_131613__sysid_feasible-v1-4__cfg-a92e984c.npy -->
  <link name="base_link">
    <inertial>
      <mass value="0.0" />
      <inertia ixx="0" ixy="0" ixz="0" iyy="0" iyz="0" izz="0" />
    </inertial>
  </link>
  <joint name="waist" type="revolute">
    <origin xyz="0.00000000 0.00000000 0.12675000" rpy="0.00000000 -0.00000000 0.00000000" />
    <parent link="base_link" />
    <child link="waist_link" />
    <axis xyz="0 0 1" />
    <limit lower="-3.141590" upper="3.141590" effort="4.100" velocity="3.141590" />
    <dynamics damping="0.06006561" friction="0.08041249" />
  </joint>
  <link name="waist_link">
    <inertial>
      <origin xyz="0.00000000 0.00000000 0.00000000" rpy="0 0 0" />
      <mass value="0.50007430" />
      <inertia ixx="0.0024833775" ixy="0.0000000000" ixz="0.0000000000" iyy="0.0024833880" iyz="0.0000000000" izz="0.0029665715" />
    </inertial>
    <!-- Identified torque offset F0[1] = -0.006722 Nm (feed-forward term, add manually to your controller) -->
  </link>
  <joint name="shoulder" type="revolute">
    <origin xyz="0.00000000 -0.00000000 0.00000000" rpy="-1.57079633 -0.00000000 -1.37287599" />
    <parent link="waist_link" />
    <child link="upper_arm_link" />
    <axis xyz="0 0 1" />
    <limit lower="-1.876300" upper="1.989700" effort="10.600" velocity="2.610500" />
    <dynamics damping="0.00000003" friction="0.72680481" />
  </joint>
  <link name="upper_arm_link">
    <inertial>
      <origin xyz="0.00150055 0.00184355 0.00120921" rpy="0 0 0" />
      <mass value="0.50007637" />
      <inertia ixx="0.1723006297" ixy="-0.0973890045" ixz="-0.0638795212" iyy="0.1329391104" iyz="-0.0785136079" izz="0.2000379775" />
    </inertial>
    <!-- Identified torque offset F0[2] = 0.179541 Nm (feed-forward term, add manually to your controller) -->
  </link>
  <joint name="elbow" type="revolute">
    <origin xyz="0.29996732 -0.06015719 0.00000000" rpy="0.00000000 -0.00000000 -0.19792034" />
    <parent link="upper_arm_link" />
    <child link="forearm_link" />
    <axis xyz="0 0 1" />
    <limit lower="-2.152100" upper="1.570800" effort="10.600" velocity="2.610500" />
    <dynamics damping="0.00000020" friction="0.55966059" />
  </joint>
  <link name="forearm_link">
    <inertial>
      <origin xyz="0.08400328 0.46454033 -0.03534038" rpy="0 0 0" />
      <mass value="0.11035692" />
      <inertia ixx="0.0355629336" ixy="-0.0020906669" ixz="0.0000359064" iyy="0.0016519902" iyz="0.0002224052" izz="0.0350067332" />
    </inertial>
    <!-- Identified torque offset F0[3] = -0.916882 Nm (feed-forward term, add manually to your controller) -->
  </link>
  <joint name="forearm_roll" type="revolute">
    <origin xyz="0.00000000 0.00000000 0.30002000" rpy="-1.57079633 -0.00000000 0.00000000" />
    <parent link="forearm_link" />
    <child link="wrist_link" />
    <axis xyz="0 0 1" />
    <limit lower="-3.141590" upper="3.141590" effort="4.100" velocity="3.141590" />
    <dynamics damping="0.54269773" friction="0.55837871" />
  </joint>
  <link name="wrist_link">
    <inertial>
      <origin xyz="0.09857936 -0.00020024 0.03804822" rpy="0 0 0" />
      <mass value="0.05017705" />
      <inertia ixx="0.0031197421" ixy="-0.0001508516" ixz="0.0000260419" iyy="0.0026448839" iyz="0.0000055048" izz="0.0023930387" />
    </inertial>
    <!-- Identified torque offset F0[4] = 0.149388 Nm (feed-forward term, add manually to your controller) -->
  </link>
  <joint name="wrist_angle" type="revolute">
    <origin xyz="0.00000000 0.00000000 0.00000000" rpy="1.57079633 -0.00000000 0.00000000" />
    <parent link="wrist_link" />
    <child link="gripper_link" />
    <axis xyz="0 0 1" />
    <limit lower="-1.745300" upper="2.146800" effort="4.100" velocity="3.141590" />
    <dynamics damping="0.00135776" friction="0.11259156" />
  </joint>
  <link name="gripper_link">
    <inertial>
      <origin xyz="0.00612453 0.00026958 0.07560308" rpy="0 0 0" />
      <mass value="0.03748222" />
      <inertia ixx="0.0023219195" ixy="0.0000051138" ixz="0.0000517035" iyy="0.0023234177" iyz="0.0000051229" izz="0.0020819417" />
    </inertial>
    <!-- Identified torque offset F0[5] = -0.122998 Nm (feed-forward term, add manually to your controller) -->
  </link>
  <joint name="wrist_rotate" type="revolute">
    <origin xyz="0.00000000 0.00000000 0.00000000" rpy="-1.57079633 -0.00000000 0.00000000" />
    <parent link="gripper_link" />
    <child link="ee_arm" />
    <axis xyz="0 0 1" />
    <limit lower="-3.141590" upper="3.141590" effort="4.100" velocity="3.141590" />
    <dynamics damping="0.00548266" friction="0.00000032" />
  </joint>
  <link name="ee_arm">
    <inertial>
      <origin xyz="0.00163658 0.00043572 0.00339524" rpy="0 0 0" />
      <mass value="0.03204451" />
      <inertia ixx="0.0020647010" ixy="-0.0000003157" ixz="0.0000021554" iyy="0.0020550680" iyz="0.0000035185" izz="0.0020264639" />
    </inertial>
    <!-- Identified torque offset F0[6] = -0.002470 Nm (feed-forward term, add manually to your controller) -->
  </link>
  <joint name="ee_arm" type="fixed">
    <origin xyz="0.13658000 0.0 0.0" rpy="0 0 0" />
    <parent link="ee_arm" />
    <child link="ee_link" />
  </joint>
  <link name="ee_link" />
</robot>