<?xml version="1.0" ?>
<robot name="viper300_sysid">
  <!-- Generated by phi_to_urdf 1.0 | phi: outputs/npy/traj_run_200hz_20260612_131613__sysid_feasible-v1-4__cfg-0a408dcb.npy -->
  <link name="base_link">
    <inertial>
      <mass value="0.0" />
      <inertia ixx="0" ixy="0" ixz="0" iyy="0" iyz="0" izz="0" />
    </inertial>
  </link>
  <joint name="waist" type="revolute">
    <origin xyz="0.00000000 0.00000000 0.12675000" rpy="0.00000000 -0.00000000 0.00000000" />
    <parent link="base_link" />
    <child link="waist_link" />
    <axis xyz="0 0 1" />
    <limit lower="-3.141590" upper="3.141590" effort="4.100" velocity="3.141590" />
    <dynamics damping="0.05956322" friction="0.08166829" />
  </joint>
  <link name="waist_link">
    <inertial>
      <origin xyz="0.00000000 0.00000000 0.00000000" rpy="0 0 0" />
      <mass value="0.50007529" />
      <inertia ixx="0.0020891626" ixy="0.0000000000" ixz="0.0000000000" iyy="0.0020891533" iyz="0.0000000000" izz="0.0021782996" />
    </inertial>
    <!-- Identified torque offset F0[1] = -0.006570 Nm (feed-forward term, add manually to your controller) -->
  </link>
  <joint name="shoulder" type="revolute">
    <origin xyz="0.00000000 -0.00000000 0.00000000" rpy="-1.57079633 -0.00000000 -1.37287599" />
    <parent link="waist_link" />
    <child link="upper_arm_link" />
    <axis xyz="0 0 1" />
    <limit lower="-1.876300" upper="1.989700" effort="10.600" velocity="2.610500" />
    <dynamics damping="0.00000007" friction="0.72728726" />
  </joint>
  <link name="upper_arm_link">
    <inertial>
      <origin xyz="0.00003266 0.00011397 0.00002600" rpy="0 0 0" />
      <mass value="0.50007786" />
      <inertia ixx="0.0023945108" ixy="-0.0003152173" ixz="-0.0000718932" iyy="0.0025775922" iyz="-0.0002556447" izz="0.0024248644" />
    </inertial>
    <!-- Identified torque offset F0[2] = 0.243441 Nm (feed-forward term, add manually to your controller) -->
  </link>
  <joint name="elbow" type="revolute">
    <origin xyz="0.29996732 -0.06015719 0.00000000" rpy="0.00000000 -0.00000000 -0.19792034" />
    <parent link="upper_arm_link" />
    <child link="forearm_link" />
    <axis xyz="0 0 1" />
    <limit lower="-2.152100" upper="1.570800" effort="10.600" velocity="2.610500" />
    <dynamics damping="0.00000047" friction="0.55969367" />
  </joint>
  <link name="forearm_link">
    <inertial>
      <origin xyz="0.02934554 0.04705821 -0.01698730" rpy="0 0 0" />
      <mass value="0.04812484" />
      <inertia ixx="0.0031467084" ixy="-0.0000519761" ixz="0.0000121865" iyy="0.0019683315" iyz="0.0000046030" izz="0.0026838042" />
    </inertial>
    <!-- Identified torque offset F0[3] = -0.881065 Nm (feed-forward term, add manually to your controller) -->
  </link>
  <joint name="forearm_roll" type="revolute">
    <origin xyz="0.00000000 0.00000000 0.30002000" rpy="-1.57079633 -0.00000000 0.00000000" />
    <parent link="forearm_link" />
    <child link="wrist_link" />
    <axis xyz="0 0 1" />
    <limit lower="-3.141590" upper="3.141590" effort="4.100" velocity="3.141590" />
    <dynamics damping="0.54241979" friction="0.55866399" />
  </joint>
  <link name="wrist_link">
    <inertial>
      <origin xyz="0.02801192 -0.00014726 0.00738439" rpy="0 0 0" />
      <mass value="0.06889912" />
      <inertia ixx="0.0021979601" ixy="-0.0000301136" ixz="0.0000044759" iyy="0.0021050497" iyz="0.0000002389" izz="0.0020703457" />
    </inertial>
    <!-- Identified torque offset F0[4] = 0.148708 Nm (feed-forward term, add manually to your controller) -->
  </link>
  <joint name="wrist_angle" type="revolute">
    <origin xyz="0.00000000 0.00000000 0.00000000" rpy="1.57079633 -0.00000000 0.00000000" />
    <parent link="wrist_link" />
    <child link="gripper_link" />
    <axis xyz="0 0 1" />
    <limit lower="-1.745300" upper="2.146800" effort="4.100" velocity="3.141590" />
    <dynamics damping="0.00170041" friction="0.11254388" />
  </joint>
  <link name="gripper_link">
    <inertial>
      <origin xyz="0.00211544 0.00015556 0.01646746" rpy="0 0 0" />
      <mass value="0.06623576" />
      <inertia ixx="0.0020674726" ixy="0.0000012798" ixz="0.0000103551" iyy="0.0020683884" iyz="0.0000010118" izz="0.0020199568" />
    </inertial>
    <!-- Identified torque offset F0[5] = -0.122951 Nm (feed-forward term, add manually to your controller) -->
  </link>
  <joint name="wrist_rotate" type="revolute">
    <origin xyz="0.00000000 0.00000000 0.00000000" rpy="-1.57079633 -0.00000000 0.00000000" />
    <parent link="gripper_link" />
    <child link="ee_arm" />
    <axis xyz="0 0 1" />
    <limit lower="-3.141590" upper="3.141590" effort="4.100" velocity="3.141590" />
    <dynamics damping="0.00548493" friction="0.00000091" />
  </joint>
  <link name="ee_arm">
    <inertial>
      <origin xyz="0.00041860 0.00025424 0.00085958" rpy="0 0 0" />
      <mass value="0.06511240" />
      <inertia ixx="0.0020155601" ixy="-0.0000000542" ixz="0.0000005065" iyy="0.0020132453" iyz="0.0000008462" izz="0.0020064588" />
    </inertial>
    <!-- Identified torque offset F0[6] = -0.002435 Nm (feed-forward term, add manually to your controller) -->
  </link>
  <joint name="ee_arm" type="fixed">
    <origin xyz="0.13658000 0.0 0.0" rpy="0 0 0" />
    <parent link="ee_arm" />
    <child link="ee_link" />
  </joint>
  <link name="ee_link" />
</robot>