<?xml version="1.0" ?>
<robot name="viper300_sysid">
  <!-- Generated by phi_to_urdf 1.0 | phi: outputs/npy/traj_run_200hz_20260612_131613__sysid_feasible-v1-4__cfg-f82ba705.npy -->
  <link name="base_link">
    <inertial>
      <mass value="0.0" />
      <inertia ixx="0" ixy="0" ixz="0" iyy="0" iyz="0" izz="0" />
    </inertial>
  </link>
  <joint name="waist" type="revolute">
    <origin xyz="0.00000000 0.00000000 0.12675000" rpy="0.00000000 -0.00000000 0.00000000" />
    <parent link="base_link" />
    <child link="waist_link" />
    <axis xyz="0 0 1" />
    <limit lower="-3.141590" upper="3.141590" effort="4.100" velocity="3.141590" />
    <dynamics damping="0.05954406" friction="0.08168674" />
  </joint>
  <link name="waist_link">
    <inertial>
      <origin xyz="0.00000000 0.00000000 0.00000000" rpy="0 0 0" />
      <mass value="0.50007728" />
      <inertia ixx="0.0020362639" ixy="0.0000000000" ixz="0.0000000000" iyy="0.0020362603" iyz="0.0000000000" izz="0.0020677125" />
    </inertial>
    <!-- Identified torque offset F0[1] = -0.006567 Nm (feed-forward term, add manually to your controller) -->
  </link>
  <joint name="shoulder" type="revolute">
    <origin xyz="0.00000000 -0.00000000 0.00000000" rpy="-1.57079633 -0.00000000 -1.37287599" />
    <parent link="waist_link" />
    <child link="upper_arm_link" />
    <axis xyz="0 0 1" />
    <limit lower="-1.876300" upper="1.989700" effort="10.600" velocity="2.610500" />
    <dynamics damping="0.00000004" friction="0.72759547" />
  </joint>
  <link name="upper_arm_link">
    <inertial>
      <origin xyz="0.00000813 0.00007062 0.00000571" rpy="0 0 0" />
      <mass value="0.50007521" />
      <inertia ixx="0.0020995175" ixy="-0.0001013321" ixz="-0.0000081933" iyy="0.0021707233" iyz="-0.0000821100" izz="0.0021022652" />
    </inertial>
    <!-- Identified torque offset F0[2] = 0.266009 Nm (feed-forward term, add manually to your controller) -->
  </link>
  <joint name="elbow" type="revolute">
    <origin xyz="0.29996732 -0.06015719 0.00000000" rpy="0.00000000 -0.00000000 -0.19792034" />
    <parent link="upper_arm_link" />
    <child link="forearm_link" />
    <axis xyz="0 0 1" />
    <limit lower="-2.152100" upper="1.570800" effort="10.600" velocity="2.610500" />
    <dynamics damping="0.00000028" friction="0.55971703" />
  </joint>
  <link name="forearm_link">
    <inertial>
      <origin xyz="0.01317817 0.01215067 -0.00590680" rpy="0 0 0" />
      <mass value="0.06006513" />
      <inertia ixx="0.0023167684" ixy="-0.0000157309" ixz="0.0000050983" iyy="0.0019617190" iyz="0.0000009581" izz="0.0021251825" />
    </inertial>
    <!-- Identified torque offset F0[3] = -0.893755 Nm (feed-forward term, add manually to your controller) -->
  </link>
  <joint name="forearm_roll" type="revolute">
    <origin xyz="0.00000000 0.00000000 0.30002000" rpy="-1.57079633 -0.00000000 0.00000000" />
    <parent link="forearm_link" />
    <child link="wrist_link" />
    <axis xyz="0 0 1" />
    <limit lower="-3.141590" upper="3.141590" effort="4.100" velocity="3.141590" />
    <dynamics damping="0.54239484" friction="0.55867469" />
  </joint>
  <link name="wrist_link">
    <inertial>
      <origin xyz="0.01150475 -0.00013813 0.00284641" rpy="0 0 0" />
      <mass value="0.07307056" />
      <inertia ixx="0.0020745473" ixy="-0.0000115663" ixz="0.0000016815" iyy="0.0020386638" iyz="0.0000000565" izz="0.0020260757" />
    </inertial>
    <!-- Identified torque offset F0[4] = 0.148716 Nm (feed-forward term, add manually to your controller) -->
  </link>
  <joint name="wrist_angle" type="revolute">
    <origin xyz="0.00000000 0.00000000 0.00000000" rpy="1.57079633 -0.00000000 0.00000000" />
    <parent link="wrist_link" />
    <child link="gripper_link" />
    <axis xyz="0 0 1" />
    <limit lower="-1.745300" upper="2.146800" effort="4.100" velocity="3.141590" />
    <dynamics damping="0.00170873" friction="0.11254519" />
  </joint>
  <link name="gripper_link">
    <inertial>
      <origin xyz="0.00089413 0.00014036 0.00649469" rpy="0 0 0" />
      <mass value="0.07254665" />
      <inertia ixx="0.0020261460" ixy="0.0000005085" ixz="0.0000039797" iyy="0.0020264963" iyz="0.0000003921" izz="0.0020078900" />
    </inertial>
    <!-- Identified torque offset F0[5] = -0.122975 Nm (feed-forward term, add manually to your controller) -->
  </link>
  <joint name="wrist_rotate" type="revolute">
    <origin xyz="0.00000000 0.00000000 0.00000000" rpy="-1.57079633 -0.00000000 0.00000000" />
    <parent link="gripper_link" />
    <child link="ee_arm" />
    <axis xyz="0 0 1" />
    <limit lower="-3.141590" upper="3.141590" effort="4.100" velocity="3.141590" />
    <dynamics damping="0.00548509" friction="0.00000056" />
  </joint>
  <link name="ee_arm">
    <inertial>
      <origin xyz="0.00017056 0.00014915 0.00034781" rpy="0 0 0" />
      <mass value="0.07232651" />
      <inertia ixx="0.0020061380" ixy="-0.0000000242" ixz="0.0000002011" iyy="0.0020052168" iyz="0.0000003356" izz="0.0020025271" />
    </inertial>
    <!-- Identified torque offset F0[6] = -0.002438 Nm (feed-forward term, add manually to your controller) -->
  </link>
  <joint name="ee_arm" type="fixed">
    <origin xyz="0.13658000 0.0 0.0" rpy="0 0 0" />
    <parent link="ee_arm" />
    <child link="ee_link" />
  </joint>
  <link name="ee_link" />
</robot>