<?xml version="1.0" ?>
<robot name="viper300_sysid">
  <!-- Generated by phi_to_urdf 1.1 | phi: outputs/npy/traj_run_200hz_20260612_131613__sysid_feasible-v1-5__cfg-a92e984c.npy -->
  <link name="base_link">
    <inertial>
      <mass value="0.0" />
      <inertia ixx="0" ixy="0" ixz="0" iyy="0" iyz="0" izz="0" />
    </inertial>
  </link>
  <joint name="waist" type="revolute">
    <origin xyz="0.00000000 -0.00000000 0.12675000" rpy="0.00000000 -0.00000000 0.00000000" />
    <parent link="base_link" />
    <child link="waist_link" />
    <axis xyz="0 0 1" />
    <limit lower="-3.141590" upper="3.141590" effort="4.100" velocity="3.141590" />
    <dynamics damping="0.05111773" friction="0.06191757" />
  </joint>
  <link name="waist_link">
    <inertial>
      <origin xyz="0.00000000 0.00000000 0.00000000" rpy="0 0 0" />
      <mass value="0.50012097" />
      <inertia ixx="0.0018928765" ixy="0.0000000000" ixz="0.0000000000" iyy="0.0018928594" iyz="0.0000000000" izz="0.0017855397" />
    </inertial>
    <!-- Identified torque offset F0[1] = -0.008919 Nm (feed-forward term, add manually to your controller) -->
  </link>
  <joint name="shoulder" type="revolute">
    <origin xyz="0.00000000 0.00000000 -0.00000000" rpy="-1.57079633 -1.37287599 0.00000000" />
    <parent link="waist_link" />
    <child link="upper_arm_link" />
    <axis xyz="0 0 1" />
    <limit lower="-1.876300" upper="1.989700" effort="10.600" velocity="2.610500" />
    <dynamics damping="0.00000003" friction="0.43783160" />
  </joint>
  <link name="upper_arm_link">
    <inertial>
      <origin xyz="-0.04083234 0.00000661 0.00060612" rpy="0 0 0" />
      <mass value="1.51296733" />
      <inertia ixx="0.0017158983" ixy="-0.0000365250" ixz="0.0000175857" iyy="0.0021407049" iyz="-0.0000202398" izz="0.0020695993" />
    </inertial>
    <!-- Identified torque offset F0[2] = -0.747614 Nm (feed-forward term, add manually to your controller) -->
  </link>
  <joint name="elbow" type="revolute">
    <origin xyz="0.30594000 -0.00000000 0.00000000" rpy="0.00000000 0.00000000 -0.19792034" />
    <parent link="upper_arm_link" />
    <child link="forearm_link" />
    <axis xyz="0 0 1" />
    <limit lower="-2.152100" upper="1.570800" effort="10.600" velocity="2.610500" />
    <dynamics damping="0.02249245" friction="0.53639675" />
  </joint>
  <link name="forearm_link">
    <inertial>
      <origin xyz="0.03895631 0.00910597 -0.00525316" rpy="0 0 0" />
      <mass value="0.76304902" />
      <inertia ixx="0.0018157528" ixy="-0.0000054982" ixz="0.0000063263" iyy="0.0015750999" iyz="0.0000368279" izz="0.0016023400" />
    </inertial>
    <!-- Identified torque offset F0[3] = 0.841843 Nm (feed-forward term, add manually to your controller) -->
  </link>
  <joint name="forearm_roll" type="revolute">
    <origin xyz="0.00000000 0.30002000 -0.00000000" rpy="-1.57079633 0.00000000 -0.00000000" />
    <parent link="forearm_link" />
    <child link="wrist_link" />
    <axis xyz="0 0 1" />
    <limit lower="-3.141590" upper="3.141590" effort="4.100" velocity="3.141590" />
    <dynamics damping="0.47491720" friction="0.55870480" />
  </joint>
  <link name="wrist_link">
    <inertial>
      <origin xyz="-0.00586197 -0.04860063 -0.01463830" rpy="0 0 0" />
      <mass value="0.35830490" />
      <inertia ixx="0.0017792474" ixy="0.0000270574" ixz="-0.0000386352" iyy="0.0017564683" iyz="0.0000195709" izz="0.0016913961" />
    </inertial>
    <!-- Identified torque offset F0[4] = -0.281497 Nm (feed-forward term, add manually to your controller) -->
  </link>
  <joint name="wrist_angle" type="revolute">
    <origin xyz="0.00000000 -0.00000000 0.00000000" rpy="1.57079633 -0.00000000 0.00000000" />
    <parent link="wrist_link" />
    <child link="gripper_link" />
    <axis xyz="0 0 1" />
    <limit lower="-1.745300" upper="2.146800" effort="4.100" velocity="3.141590" />
    <dynamics damping="0.02241330" friction="0.07298549" />
  </joint>
  <link name="gripper_link">
    <inertial>
      <origin xyz="0.00103935 0.02039268 0.04843300" rpy="0 0 0" />
      <mass value="0.38398004" />
      <inertia ixx="0.0017780507" ixy="0.0000073489" ixz="0.0000098390" iyy="0.0019106330" iyz="0.0000285665" izz="0.0019744691" />
    </inertial>
    <!-- Identified torque offset F0[5] = -0.027148 Nm (feed-forward term, add manually to your controller) -->
  </link>
  <joint name="wrist_rotate" type="revolute">
    <origin xyz="0.00000000 0.00000000 -0.00000000" rpy="-1.57079633 0.00000000 -0.00000000" />
    <parent link="gripper_link" />
    <child link="ee_arm" />
    <axis xyz="0 0 1" />
    <limit lower="-3.141590" upper="3.141590" effort="4.100" velocity="3.141590" />
    <dynamics damping="0.00176547" friction="0.00000014" />
  </joint>
  <link name="ee_arm">
    <inertial>
      <origin xyz="-0.00075904 0.00050482 0.02201677" rpy="0 0 0" />
      <mass value="0.18716662" />
      <inertia ixx="0.0018634202" ixy="0.0000000123" ixz="0.0000018318" iyy="0.0018864824" iyz="-0.0000004208" izz="0.0019099806" />
    </inertial>
    <!-- Identified torque offset F0[6] = -0.000041 Nm (feed-forward term, add manually to your controller) -->
  </link>
  <joint name="ee_arm" type="fixed">
    <origin xyz="0.13658000 0.0 0.0" rpy="0 0 0" />
    <parent link="ee_arm" />
    <child link="ee_link" />
  </joint>
  <link name="ee_link" />
</robot>