<?xml version="1.0" ?>
<robot name="viper300_sysid">
  <!-- Generated by phi_to_urdf 1.0 | phi: outputs/npy/traj_run_200hz_20260612_131613__sysid_feasible-v1-4__cfg-b2a57dff.npy -->
  <link name="base_link">
    <inertial>
      <mass value="0.0" />
      <inertia ixx="0" ixy="0" ixz="0" iyy="0" iyz="0" izz="0" />
    </inertial>
  </link>
  <joint name="waist" type="revolute">
    <origin xyz="0.00000000 0.00000000 0.12675000" rpy="0.00000000 -0.00000000 0.00000000" />
    <parent link="base_link" />
    <child link="waist_link" />
    <axis xyz="0 0 1" />
    <limit lower="-3.141590" upper="3.141590" effort="4.100" velocity="3.141590" />
    <dynamics damping="0.05952455" friction="0.08169008" />
  </joint>
  <link name="waist_link">
    <inertial>
      <origin xyz="0.00000000 0.00000000 0.00000000" rpy="0 0 0" />
      <mass value="0.50000947" />
      <inertia ixx="0.0020166654" ixy="0.0000000000" ixz="0.0000000000" iyy="0.0020166646" iyz="0.0000000000" izz="0.0020333295" />
    </inertial>
    <!-- Identified torque offset F0[1] = -0.006567 Nm (feed-forward term, add manually to your controller) -->
  </link>
  <joint name="shoulder" type="revolute">
    <origin xyz="0.00000000 -0.00000000 0.00000000" rpy="-1.57079633 -0.00000000 -1.37287599" />
    <parent link="waist_link" />
    <child link="upper_arm_link" />
    <axis xyz="0 0 1" />
    <limit lower="-1.876300" upper="1.989700" effort="10.600" velocity="2.610500" />
    <dynamics damping="0.00000004" friction="0.72798548" />
  </joint>
  <link name="upper_arm_link">
    <inertial>
      <origin xyz="0.00000175 0.00003717 0.00000145" rpy="0 0 0" />
      <mass value="0.50000996" />
      <inertia ixx="0.0020422359" ixy="-0.0000482856" ixz="-0.0000018799" iyy="0.0020775192" iyz="-0.0000390847" izz="0.0020430352" />
    </inertial>
    <!-- Identified torque offset F0[2] = 0.295414 Nm (feed-forward term, add manually to your controller) -->
  </link>
  <joint name="elbow" type="revolute">
    <origin xyz="0.29996732 -0.06015719 0.00000000" rpy="0.00000000 -0.00000000 -0.19792034" />
    <parent link="upper_arm_link" />
    <child link="forearm_link" />
    <axis xyz="0 0 1" />
    <limit lower="-2.152100" upper="1.570800" effort="10.600" velocity="2.610500" />
    <dynamics damping="0.00000026" friction="0.55974133" />
  </joint>
  <link name="forearm_link">
    <inertial>
      <origin xyz="0.00677177 0.00540440 -0.00285247" rpy="0 0 0" />
      <mass value="0.07278298" />
      <inertia ixx="0.0021449844" ixy="-0.0000074477" ixz="0.0000026405" iyy="0.0019758058" iyz="0.0000003939" izz="0.0020470995" />
    </inertial>
    <!-- Identified torque offset F0[3] = -0.911307 Nm (feed-forward term, add manually to your controller) -->
  </link>
  <joint name="forearm_roll" type="revolute">
    <origin xyz="0.00000000 0.00000000 0.30002000" rpy="-1.57079633 -0.00000000 0.00000000" />
    <parent link="forearm_link" />
    <child link="wrist_link" />
    <axis xyz="0 0 1" />
    <limit lower="-3.141590" upper="3.141590" effort="4.100" velocity="3.141590" />
    <dynamics damping="0.54236489" friction="0.55868499" />
  </joint>
  <link name="wrist_link">
    <inertial>
      <origin xyz="0.00579928 -0.00012336 0.00140245" rpy="0 0 0" />
      <mass value="0.08174276" />
      <inertia ixx="0.0020359394" ixy="-0.0000057099" ixz="0.0000008240" iyy="0.0020182171" iyz="0.0000000230" izz="0.0020127711" />
    </inertial>
    <!-- Identified torque offset F0[4] = 0.148735 Nm (feed-forward term, add manually to your controller) -->
  </link>
  <joint name="wrist_angle" type="revolute">
    <origin xyz="0.00000000 0.00000000 0.00000000" rpy="1.57079633 -0.00000000 0.00000000" />
    <parent link="wrist_link" />
    <child link="gripper_link" />
    <axis xyz="0 0 1" />
    <limit lower="-1.745300" upper="2.146800" effort="4.100" velocity="3.141590" />
    <dynamics damping="0.00171846" friction="0.11254699" />
  </joint>
  <link name="gripper_link">
    <inertial>
      <origin xyz="0.00045468 0.00012463 0.00322866" rpy="0 0 0" />
      <mass value="0.08158247" />
      <inertia ixx="0.0020130053" ixy="0.0000002532" ixz="0.0000019642" iyy="0.0020124624" iyz="0.0000001942" izz="0.0020046797" />
    </inertial>
    <!-- Identified torque offset F0[5] = -0.123008 Nm (feed-forward term, add manually to your controller) -->
  </link>
  <joint name="wrist_rotate" type="revolute">
    <origin xyz="0.00000000 0.00000000 0.00000000" rpy="-1.57079633 -0.00000000 0.00000000" />
    <parent link="gripper_link" />
    <child link="ee_arm" />
    <axis xyz="0 0 1" />
    <limit lower="-3.141590" upper="3.141590" effort="4.100" velocity="3.141590" />
    <dynamics damping="0.00548568" friction="0.00000050" />
  </joint>
  <link name="ee_arm">
    <inertial>
      <origin xyz="0.00008593 0.00013145 0.00017458" rpy="0 0 0" />
      <mass value="0.08151679" />
      <inertia ixx="0.0020019173" ixy="-0.0000000120" ixz="0.0000001004" iyy="0.0020026346" iyz="0.0000001671" izz="0.0020001162" />
    </inertial>
    <!-- Identified torque offset F0[6] = -0.002442 Nm (feed-forward term, add manually to your controller) -->
  </link>
  <joint name="ee_arm" type="fixed">
    <origin xyz="0.13658000 0.0 0.0" rpy="0 0 0" />
    <parent link="ee_arm" />
    <child link="ee_link" />
  </joint>
  <link name="ee_link" />
</robot>