<?xml version="1.0" ?>
<robot name="viper300_sysid">
  <!-- Generated by phi_to_urdf 1.0 | phi: outputs/npy/traj_run_200hz_20260612_131613__sysid_feasible-v1-4__cfg-231870fb.npy -->
  <link name="base_link">
    <inertial>
      <mass value="0.0" />
      <inertia ixx="0" ixy="0" ixz="0" iyy="0" iyz="0" izz="0" />
    </inertial>
  </link>
  <joint name="waist" type="revolute">
    <origin xyz="0.00000000 0.00000000 0.12675000" rpy="0.00000000 -0.00000000 0.00000000" />
    <parent link="base_link" />
    <child link="waist_link" />
    <axis xyz="0 0 1" />
    <limit lower="-3.141590" upper="3.141590" effort="4.100" velocity="3.141590" />
    <dynamics damping="0.15661988" friction="0.25783675" />
  </joint>
  <link name="waist_link">
    <inertial>
      <origin xyz="0.01338482 0.01958478 0.00364266" rpy="0 0 0" />
      <mass value="0.81529225" />
      <inertia ixx="0.0326463939" ixy="-0.0001966156" ixz="0.0002448195" iyy="0.0308745239" iyz="0.0006124333" izz="0.0331481237" />
    </inertial>
    <!-- Identified torque offset F0[1] = -0.052358 Nm (feed-forward term, add manually to your controller) -->
  </link>
  <joint name="shoulder" type="revolute">
    <origin xyz="0.00000000 -0.00000000 0.00000000" rpy="-1.57079633 -0.00000000 -1.37287599" />
    <parent link="waist_link" />
    <child link="upper_arm_link" />
    <axis xyz="0 0 1" />
    <limit lower="-1.876300" upper="1.989700" effort="10.600" velocity="2.610500" />
    <dynamics damping="0.13444801" friction="0.43173232" />
  </joint>
  <link name="upper_arm_link">
    <inertial>
      <origin xyz="0.01151899 0.04361353 -0.00710721" rpy="0 0 0" />
      <mass value="0.81187208" />
      <inertia ixx="0.0423760270" ixy="-0.0017436687" ixz="0.0002201309" iyy="0.0470292609" iyz="0.0016652938" izz="0.0497226843" />
    </inertial>
    <!-- Identified torque offset F0[2] = -0.186423 Nm (feed-forward term, add manually to your controller) -->
  </link>
  <joint name="elbow" type="revolute">
    <origin xyz="0.29996732 -0.06015719 0.00000000" rpy="0.00000000 -0.00000000 -0.19792034" />
    <parent link="upper_arm_link" />
    <child link="forearm_link" />
    <axis xyz="0 0 1" />
    <limit lower="-2.152100" upper="1.570800" effort="10.600" velocity="2.610500" />
    <dynamics damping="0.06334384" friction="0.28322298" />
  </joint>
  <link name="forearm_link">
    <inertial>
      <origin xyz="0.00135928 0.06357940 0.00699062" rpy="0 0 0" />
      <mass value="0.51768873" />
      <inertia ixx="0.0402102611" ixy="0.0011646706" ixz="-0.0028867608" iyy="0.0444424434" iyz="-0.0025106492" izz="0.0385323449" />
    </inertial>
    <!-- Identified torque offset F0[3] = -0.767152 Nm (feed-forward term, add manually to your controller) -->
  </link>
  <joint name="forearm_roll" type="revolute">
    <origin xyz="0.00000000 0.00000000 0.30002000" rpy="-1.57079633 -0.00000000 0.00000000" />
    <parent link="forearm_link" />
    <child link="wrist_link" />
    <axis xyz="0 0 1" />
    <limit lower="-3.141590" upper="3.141590" effort="4.100" velocity="3.141590" />
    <dynamics damping="0.04350255" friction="0.06535604" />
  </joint>
  <link name="wrist_link">
    <inertial>
      <origin xyz="0.01913133 -0.10081077 0.01071904" rpy="0 0 0" />
      <mass value="0.32390351" />
      <inertia ixx="0.0416173608" ixy="-0.0025327076" ixz="0.0002679627" iyy="0.0422235762" iyz="0.0036822282" izz="0.0384773407" />
    </inertial>
    <!-- Identified torque offset F0[4] = 0.005420 Nm (feed-forward term, add manually to your controller) -->
  </link>
  <joint name="wrist_angle" type="revolute">
    <origin xyz="0.00000000 0.00000000 0.00000000" rpy="1.57079633 -0.00000000 0.00000000" />
    <parent link="wrist_link" />
    <child link="gripper_link" />
    <axis xyz="0 0 1" />
    <limit lower="-1.745300" upper="2.146800" effort="4.100" velocity="3.141590" />
    <dynamics damping="0.03435867" friction="0.08801504" />
  </joint>
  <link name="gripper_link">
    <inertial>
      <origin xyz="-0.01362272 0.12914253 0.05609880" rpy="0 0 0" />
      <mass value="0.21932631" />
      <inertia ixx="0.0330336318" ixy="-0.0023949036" ixz="0.0046821594" iyy="0.0414506710" iyz="-0.0011358199" izz="0.0395672483" />
    </inertial>
    <!-- Identified torque offset F0[5] = -0.013261 Nm (feed-forward term, add manually to your controller) -->
  </link>
  <joint name="wrist_rotate" type="revolute">
    <origin xyz="0.00000000 0.00000000 0.00000000" rpy="-1.57079633 -0.00000000 0.00000000" />
    <parent link="gripper_link" />
    <child link="ee_arm" />
    <axis xyz="0 0 1" />
    <limit lower="-3.141590" upper="3.141590" effort="4.100" velocity="3.141590" />
    <dynamics damping="0.02799313" friction="0.03318245" />
  </joint>
  <link name="ee_arm">
    <inertial>
      <origin xyz="0.06990754 0.11334980 0.02001585" rpy="0 0 0" />
      <mass value="0.13724823" />
      <inertia ixx="0.0403447152" ixy="-0.0008817384" ixz="0.0002635917" iyy="0.0392546898" iyz="0.0020326097" izz="0.0445976255" />
    </inertial>
    <!-- Identified torque offset F0[6] = -0.004295 Nm (feed-forward term, add manually to your controller) -->
  </link>
  <joint name="ee_arm" type="fixed">
    <origin xyz="0.13658000 0.0 0.0" rpy="0 0 0" />
    <parent link="ee_arm" />
    <child link="ee_link" />
  </joint>
  <link name="ee_link" />
</robot>