<?xml version="1.0" ?>
<robot name="viper300_sysid">
  <!-- Generated by phi_to_urdf 1.0 | phi: outputs/npy/traj_run_20260518_143818__sysid_feasible-v1-4__cfg-f8c3b062.npy -->
  <link name="base_link">
    <inertial>
      <mass value="0.0" />
      <inertia ixx="0" ixy="0" ixz="0" iyy="0" iyz="0" izz="0" />
    </inertial>
  </link>
  <joint name="waist" type="revolute">
    <origin xyz="0.00000000 0.00000000 0.12675000" rpy="0.00000000 -0.00000000 0.00000000" />
    <parent link="base_link" />
    <child link="waist_link" />
    <axis xyz="0 0 1" />
    <limit lower="-3.141590" upper="3.141590" effort="4.100" velocity="3.141590" />
    <dynamics damping="0.13620335" friction="0.24585201" />
  </joint>
  <link name="waist_link">
    <inertial>
      <origin xyz="-0.01045932 0.01986974 -0.00500134" rpy="0 0 0" />
      <mass value="0.80183984" />
      <inertia ixx="0.0006387628" ixy="-0.0000179619" ixz="0.0000489709" iyy="0.0006628179" iyz="0.0000481918" izz="0.0006670058" />
    </inertial>
    <!-- Identified torque offset F0[1] = -0.048966 Nm (feed-forward term, add manually to your controller) -->
  </link>
  <joint name="shoulder" type="revolute">
    <origin xyz="0.00000000 -0.00000000 0.00000000" rpy="-1.57079633 -0.00000000 -1.37287599" />
    <parent link="waist_link" />
    <child link="upper_arm_link" />
    <axis xyz="0 0 1" />
    <limit lower="-1.876300" upper="1.989700" effort="10.600" velocity="2.610500" />
    <dynamics damping="0.11261909" friction="0.41760206" />
  </joint>
  <link name="upper_arm_link">
    <inertial>
      <origin xyz="-0.01416684 0.04185992 0.02092439" rpy="0 0 0" />
      <mass value="0.79937205" />
      <inertia ixx="0.0141684440" ixy="-0.0046483283" ixz="0.0062804359" iyy="0.0192136214" iyz="0.0037844397" izz="0.0192950536" />
    </inertial>
    <!-- Identified torque offset F0[2] = -0.203911 Nm (feed-forward term, add manually to your controller) -->
  </link>
  <joint name="elbow" type="revolute">
    <origin xyz="0.29996732 -0.06015719 0.00000000" rpy="0.00000000 -0.00000000 -0.19792034" />
    <parent link="upper_arm_link" />
    <child link="forearm_link" />
    <axis xyz="0 0 1" />
    <limit lower="-2.152100" upper="1.570800" effort="10.600" velocity="2.610500" />
    <dynamics damping="0.04541210" friction="0.26615258" />
  </joint>
  <link name="forearm_link">
    <inertial>
      <origin xyz="0.00769622 0.07041504 0.00112920" rpy="0 0 0" />
      <mass value="0.50939765" />
      <inertia ixx="0.0129397771" ixy="-0.0012050977" ixz="0.0031270964" iyy="0.0130327604" iyz="0.0036638931" izz="0.0177735569" />
    </inertial>
    <!-- Identified torque offset F0[3] = -0.761007 Nm (feed-forward term, add manually to your controller) -->
  </link>
  <joint name="forearm_roll" type="revolute">
    <origin xyz="0.00000000 0.00000000 0.30002000" rpy="-1.57079633 -0.00000000 0.00000000" />
    <parent link="forearm_link" />
    <child link="wrist_link" />
    <axis xyz="0 0 1" />
    <limit lower="-3.141590" upper="3.141590" effort="4.100" velocity="3.141590" />
    <dynamics damping="0.02811111" friction="0.04219345" />
  </joint>
  <link name="wrist_link">
    <inertial>
      <origin xyz="-0.01414347 -0.06192332 0.00036917" rpy="0 0 0" />
      <mass value="0.30089873" />
      <inertia ixx="0.0085574213" ixy="-0.0000178113" ixz="-0.0001522240" iyy="0.0085328715" iyz="0.0004025392" izz="0.0027837359" />
    </inertial>
    <!-- Identified torque offset F0[4] = 0.013990 Nm (feed-forward term, add manually to your controller) -->
  </link>
  <joint name="wrist_angle" type="revolute">
    <origin xyz="0.00000000 0.00000000 0.00000000" rpy="1.57079633 -0.00000000 0.00000000" />
    <parent link="wrist_link" />
    <child link="gripper_link" />
    <axis xyz="0 0 1" />
    <limit lower="-1.745300" upper="2.146800" effort="4.100" velocity="3.141590" />
    <dynamics damping="0.03596495" friction="0.06941097" />
  </joint>
  <link name="gripper_link">
    <inertial>
      <origin xyz="0.00767378 0.07151655 -0.00835564" rpy="0 0 0" />
      <mass value="0.20916166" />
      <inertia ixx="0.0104626745" ixy="-0.0009161019" ixz="-0.0004178124" iyy="0.0157864369" iyz="-0.0018515191" izz="0.0142551780" />
    </inertial>
    <!-- Identified torque offset F0[5] = -0.014738 Nm (feed-forward term, add manually to your controller) -->
  </link>
  <joint name="wrist_rotate" type="revolute">
    <origin xyz="0.00000000 0.00000000 0.00000000" rpy="-1.57079633 -0.00000000 0.00000000" />
    <parent link="gripper_link" />
    <child link="ee_arm" />
    <axis xyz="0 0 1" />
    <limit lower="-3.141590" upper="3.141590" effort="4.100" velocity="3.141590" />
    <dynamics damping="0.00795125" friction="0.01046625" />
  </joint>
  <link name="ee_arm">
    <inertial>
      <origin xyz="0.12150763 0.09199909 -0.07081300" rpy="0 0 0" />
      <mass value="0.10781429" />
      <inertia ixx="0.0134405093" ixy="0.0026027171" ixz="0.0064693906" iyy="0.0151995149" iyz="-0.0046431108" izz="0.0055261229" />
    </inertial>
    <!-- Identified torque offset F0[6] = -0.000405 Nm (feed-forward term, add manually to your controller) -->
  </link>
  <joint name="ee_arm" type="fixed">
    <origin xyz="0.13658000 0.0 0.0" rpy="0 0 0" />
    <parent link="ee_arm" />
    <child link="ee_link" />
  </joint>
  <link name="ee_link" />
</robot>