<?xml version="1.0" ?>
<robot name="viper300_sysid">
  <!-- Generated by phi_to_urdf 1.0 | phi: outputs/npy/traj_run_200hz_20260612_131613__sysid_feasible-v1-4__cfg-43fd85c7.npy -->
  <link name="base_link">
    <inertial>
      <mass value="0.0" />
      <inertia ixx="0" ixy="0" ixz="0" iyy="0" iyz="0" izz="0" />
    </inertial>
  </link>
  <joint name="waist" type="revolute">
    <origin xyz="0.00000000 0.00000000 0.12675000" rpy="0.00000000 -0.00000000 0.00000000" />
    <parent link="base_link" />
    <child link="waist_link" />
    <axis xyz="0 0 1" />
    <limit lower="-3.141590" upper="3.141590" effort="4.100" velocity="3.141590" />
    <dynamics damping="0.05949565" friction="0.08168700" />
  </joint>
  <link name="waist_link">
    <inertial>
      <origin xyz="0.00000000 0.00000000 0.00000000" rpy="0 0 0" />
      <mass value="0.50001096" />
      <inertia ixx="0.0020084692" ixy="0.0000000000" ixz="0.0000000000" iyy="0.0020081028" iyz="0.0000000000" izz="0.0020168336" />
    </inertial>
    <!-- Identified torque offset F0[1] = -0.006567 Nm (feed-forward term, add manually to your controller) -->
  </link>
  <joint name="shoulder" type="revolute">
    <origin xyz="0.00000000 -0.00000000 0.00000000" rpy="-1.57079633 -0.00000000 -1.37287599" />
    <parent link="waist_link" />
    <child link="upper_arm_link" />
    <axis xyz="0 0 1" />
    <limit lower="-1.876300" upper="1.989700" effort="10.600" velocity="2.610500" />
    <dynamics damping="0.00000006" friction="0.72856859" />
  </joint>
  <link name="upper_arm_link">
    <inertial>
      <origin xyz="0.00000073 0.00003293 0.00000063" rpy="0 0 0" />
      <mass value="0.50001190" />
      <inertia ixx="0.0020178622" ixy="-0.0000236524" ixz="-0.0000004520" iyy="0.0020356938" iyz="-0.0000191016" izz="0.0020168241" />
    </inertial>
    <!-- Identified torque offset F0[2] = 0.339701 Nm (feed-forward term, add manually to your controller) -->
  </link>
  <joint name="elbow" type="revolute">
    <origin xyz="0.29996732 -0.06015719 0.00000000" rpy="0.00000000 -0.00000000 -0.19792034" />
    <parent link="upper_arm_link" />
    <child link="forearm_link" />
    <axis xyz="0 0 1" />
    <limit lower="-2.152100" upper="1.570800" effort="10.600" velocity="2.610500" />
    <dynamics damping="0.00000045" friction="0.55977628" />
  </joint>
  <link name="forearm_link">
    <inertial>
      <origin xyz="0.00334353 0.00255029 -0.00143338" rpy="0 0 0" />
      <mass value="0.08962076" />
      <inertia ixx="0.0020679404" ixy="-0.0000036476" ixz="0.0000013682" iyy="0.0019862717" iyz="0.0000001772" izz="0.0020185775" />
    </inertial>
    <!-- Identified torque offset F0[3] = -0.937772 Nm (feed-forward term, add manually to your controller) -->
  </link>
  <joint name="forearm_roll" type="revolute">
    <origin xyz="0.00000000 0.00000000 0.30002000" rpy="-1.57079633 -0.00000000 0.00000000" />
    <parent link="forearm_link" />
    <child link="wrist_link" />
    <axis xyz="0 0 1" />
    <limit lower="-3.141590" upper="3.141590" effort="4.100" velocity="3.141590" />
    <dynamics damping="0.54231879" friction="0.55870019" />
  </joint>
  <link name="wrist_link">
    <inertial>
      <origin xyz="0.00291156 -0.00010558 0.00069500" rpy="0 0 0" />
      <mass value="0.09598022" />
      <inertia ixx="0.0020178445" ixy="-0.0000028382" ixz="0.0000004086" iyy="0.0020097701" iyz="0.0000000104" izz="0.0020069986" />
    </inertial>
    <!-- Identified torque offset F0[4] = 0.148765 Nm (feed-forward term, add manually to your controller) -->
  </link>
  <joint name="wrist_angle" type="revolute">
    <origin xyz="0.00000000 0.00000000 0.00000000" rpy="1.57079633 -0.00000000 0.00000000" />
    <parent link="wrist_link" />
    <child link="gripper_link" />
    <axis xyz="0 0 1" />
    <limit lower="-1.745300" upper="2.146800" effort="4.100" velocity="3.141590" />
    <dynamics damping="0.00173572" friction="0.11254950" />
  </joint>
  <link name="gripper_link">
    <inertial>
      <origin xyz="0.00022904 0.00010717 0.00160920" rpy="0 0 0" />
      <mass value="0.09592239" />
      <inertia ixx="0.0020052619" ixy="0.0000001262" ixz="0.0000009758" iyy="0.0020052365" iyz="0.0000000967" izz="0.0020017349" />
    </inertial>
    <!-- Identified torque offset F0[5] = -0.123056 Nm (feed-forward term, add manually to your controller) -->
  </link>
  <joint name="wrist_rotate" type="revolute">
    <origin xyz="0.00000000 0.00000000 0.00000000" rpy="-1.57079633 -0.00000000 0.00000000" />
    <parent link="gripper_link" />
    <child link="ee_arm" />
    <axis xyz="0 0 1" />
    <limit lower="-3.141590" upper="3.141590" effort="4.100" velocity="3.141590" />
    <dynamics damping="0.00548708" friction="0.00000082" />
  </joint>
  <link name="ee_arm">
    <inertial>
      <origin xyz="0.00004323 0.00013349 0.00008749" rpy="0 0 0" />
      <mass value="0.09589841" />
      <inertia ixx="0.0020025919" ixy="-0.0000000058" ixz="0.0000000502" iyy="0.0020014727" iyz="0.0000000837" izz="0.0020021027" />
    </inertial>
    <!-- Identified torque offset F0[6] = -0.002447 Nm (feed-forward term, add manually to your controller) -->
  </link>
  <joint name="ee_arm" type="fixed">
    <origin xyz="0.13658000 0.0 0.0" rpy="0 0 0" />
    <parent link="ee_arm" />
    <child link="ee_link" />
  </joint>
  <link name="ee_link" />
</robot>