<?xml version="1.0" ?>
<robot name="viper300_sysid">
  <!-- Generated by phi_to_urdf 1.1 | phi: outputs/npy/traj_run_200hz_20260612_131613__sysid_feasible-v1-5__cfg-9ef2c992.npy -->
  <link name="base_link">
    <inertial>
      <mass value="0.0" />
      <inertia ixx="0" ixy="0" ixz="0" iyy="0" iyz="0" izz="0" />
    </inertial>
  </link>
  <joint name="waist" type="revolute">
    <origin xyz="0.00000000 -0.00000000 0.12675000" rpy="0.00000000 -0.00000000 0.00000000" />
    <parent link="base_link" />
    <child link="waist_link" />
    <axis xyz="0 0 1" />
    <limit lower="-3.141590" upper="3.141590" effort="4.100" velocity="3.141590" />
    <dynamics damping="0.05048934" friction="0.06218513" />
  </joint>
  <link name="waist_link">
    <inertial>
      <origin xyz="0.00000000 0.00000000 0.00000000" rpy="0 0 0" />
      <mass value="0.50065886" />
      <inertia ixx="0.0018711597" ixy="0.0000000000" ixz="0.0000000000" iyy="0.0018710664" iyz="0.0000000000" izz="0.0017405736" />
    </inertial>
    <!-- Identified torque offset F0[1] = -0.008907 Nm (feed-forward term, add manually to your controller) -->
  </link>
  <joint name="shoulder" type="revolute">
    <origin xyz="0.00000000 0.00000000 -0.00000000" rpy="-1.57079633 -1.37287599 0.00000000" />
    <parent link="waist_link" />
    <child link="upper_arm_link" />
    <axis xyz="0 0 1" />
    <limit lower="-1.876300" upper="1.989700" effort="10.600" velocity="2.610500" />
    <dynamics damping="0.00000053" friction="0.44225841" />
  </joint>
  <link name="upper_arm_link">
    <inertial>
      <origin xyz="-0.04208780 0.00000591 0.00062686" rpy="0 0 0" />
      <mass value="1.71416555" />
      <inertia ixx="0.0016423267" ixy="-0.0000397725" ixz="0.0000175464" iyy="0.0021261432" iyz="-0.0000214778" izz="0.0020258617" />
    </inertial>
    <!-- Identified torque offset F0[2] = -0.799553 Nm (feed-forward term, add manually to your controller) -->
  </link>
  <joint name="elbow" type="revolute">
    <origin xyz="0.30594000 -0.00000000 0.00000000" rpy="0.00000000 0.00000000 -0.19792034" />
    <parent link="upper_arm_link" />
    <child link="forearm_link" />
    <axis xyz="0 0 1" />
    <limit lower="-2.152100" upper="1.570800" effort="10.600" velocity="2.610500" />
    <dynamics damping="0.02328025" friction="0.53615327" />
  </joint>
  <link name="forearm_link">
    <inertial>
      <origin xyz="0.03670898 0.01727059 -0.00557878" rpy="0 0 0" />
      <mass value="0.79822273" />
      <inertia ixx="0.0017412398" ixy="-0.0000059029" ixz="0.0000059448" iyy="0.0014855716" iyz="0.0000344052" izz="0.0014831060" />
    </inertial>
    <!-- Identified torque offset F0[3] = 0.851672 Nm (feed-forward term, add manually to your controller) -->
  </link>
  <joint name="forearm_roll" type="revolute">
    <origin xyz="0.00000000 0.30002000 -0.00000000" rpy="-1.57079633 0.00000000 -0.00000000" />
    <parent link="forearm_link" />
    <child link="wrist_link" />
    <axis xyz="0 0 1" />
    <limit lower="-3.141590" upper="3.141590" effort="4.100" velocity="3.141590" />
    <dynamics damping="0.47509458" friction="0.55862240" />
  </joint>
  <link name="wrist_link">
    <inertial>
      <origin xyz="-0.00656571 -0.04954191 -0.02222698" rpy="0 0 0" />
      <mass value="0.38506250" />
      <inertia ixx="0.0017859037" ixy="0.0000332222" ixz="-0.0000421563" iyy="0.0018381118" iyz="0.0000204295" izz="0.0018835191" />
    </inertial>
    <!-- Identified torque offset F0[4] = -0.281147 Nm (feed-forward term, add manually to your controller) -->
  </link>
  <joint name="wrist_angle" type="revolute">
    <origin xyz="0.00000000 -0.00000000 0.00000000" rpy="1.57079633 -0.00000000 0.00000000" />
    <parent link="wrist_link" />
    <child link="gripper_link" />
    <axis xyz="0 0 1" />
    <limit lower="-1.745300" upper="2.146800" effort="4.100" velocity="3.141590" />
    <dynamics damping="0.02245719" friction="0.07298180" />
  </joint>
  <link name="gripper_link">
    <inertial>
      <origin xyz="0.00096567 0.02103004 0.04953728" rpy="0 0 0" />
      <mass value="0.36667489" />
      <inertia ixx="0.0018619892" ixy="0.0000070079" ixz="0.0000097452" iyy="0.0018992697" iyz="0.0000314164" izz="0.0019309871" />
    </inertial>
    <!-- Identified torque offset F0[5] = -0.027074 Nm (feed-forward term, add manually to your controller) -->
  </link>
  <joint name="wrist_rotate" type="revolute">
    <origin xyz="0.00000000 0.00000000 -0.00000000" rpy="-1.57079633 0.00000000 -0.00000000" />
    <parent link="gripper_link" />
    <child link="ee_arm" />
    <axis xyz="0 0 1" />
    <limit lower="-3.141590" upper="3.141590" effort="4.100" velocity="3.141590" />
    <dynamics damping="0.00183025" friction="0.00000371" />
  </joint>
  <link name="ee_arm">
    <inertial>
      <origin xyz="-0.00079267 0.00106855 0.02274017" rpy="0 0 0" />
      <mass value="0.18486878" />
      <inertia ixx="0.0018658623" ixy="-0.0000000738" ixz="0.0000020069" iyy="0.0019673206" iyz="0.0000002893" izz="0.0019416060" />
    </inertial>
    <!-- Identified torque offset F0[6] = -0.000069 Nm (feed-forward term, add manually to your controller) -->
  </link>
  <joint name="ee_arm" type="fixed">
    <origin xyz="0.13658000 0.0 0.0" rpy="0 0 0" />
    <parent link="ee_arm" />
    <child link="ee_link" />
  </joint>
  <link name="ee_link" />
</robot>