<?xml version="1.0" ?>
<robot name="viper300_sysid">
  <!-- Generated by phi_to_urdf 1.0 | phi: outputs/npy/traj_run_200hz_20260612_161025__sysid_feasible-v1-4__cfg-a92e984c.npy -->
  <link name="base_link">
    <inertial>
      <mass value="0.0" />
      <inertia ixx="0" ixy="0" ixz="0" iyy="0" iyz="0" izz="0" />
    </inertial>
  </link>
  <joint name="waist" type="revolute">
    <origin xyz="0.00000000 0.00000000 0.12675000" rpy="0.00000000 -0.00000000 0.00000000" />
    <parent link="base_link" />
    <child link="waist_link" />
    <axis xyz="0 0 1" />
    <limit lower="-3.141590" upper="3.141590" effort="4.100" velocity="3.141590" />
    <dynamics damping="0.05673413" friction="0.06294374" />
  </joint>
  <link name="waist_link">
    <inertial>
      <origin xyz="0.00000000 0.00000000 0.00000000" rpy="0 0 0" />
      <mass value="0.50028577" />
      <inertia ixx="0.0023409766" ixy="0.0000000000" ixz="0.0000000000" iyy="0.0023409662" iyz="0.0000000000" izz="0.0026811687" />
    </inertial>
    <!-- Identified torque offset F0[1] = -0.007063 Nm (feed-forward term, add manually to your controller) -->
  </link>
  <joint name="shoulder" type="revolute">
    <origin xyz="0.00000000 -0.00000000 0.00000000" rpy="-1.57079633 -0.00000000 -1.37287599" />
    <parent link="waist_link" />
    <child link="upper_arm_link" />
    <axis xyz="0 0 1" />
    <limit lower="-1.876300" upper="1.989700" effort="10.600" velocity="2.610500" />
    <dynamics damping="0.00000003" friction="0.65115650" />
  </joint>
  <link name="upper_arm_link">
    <inertial>
      <origin xyz="0.00095114 0.00112674 0.00064244" rpy="0 0 0" />
      <mass value="0.50028942" />
      <inertia ixx="0.0514163222" ixy="-0.0321083614" ixz="-0.0183030642" iyy="0.0416119807" iyz="-0.0216622564" izz="0.0661978516" />
    </inertial>
    <!-- Identified torque offset F0[2] = 1.463743 Nm (feed-forward term, add manually to your controller) -->
  </link>
  <joint name="elbow" type="revolute">
    <origin xyz="0.29996732 -0.06015719 0.00000000" rpy="0.00000000 -0.00000000 -0.19792034" />
    <parent link="upper_arm_link" />
    <child link="forearm_link" />
    <axis xyz="0 0 1" />
    <limit lower="-2.152100" upper="1.570800" effort="10.600" velocity="2.610500" />
    <dynamics damping="0.02323630" friction="0.53602397" />
  </joint>
  <link name="forearm_link">
    <inertial>
      <origin xyz="0.00901599 0.14259946 -0.01051979" rpy="0 0 0" />
      <mass value="0.25842684" />
      <inertia ixx="0.0586174232" ixy="-0.0038835247" ixz="0.0000730543" iyy="0.0018641276" iyz="-0.0005989956" izz="0.0582839910" />
    </inertial>
    <!-- Identified torque offset F0[3] = -1.726102 Nm (feed-forward term, add manually to your controller) -->
  </link>
  <joint name="forearm_roll" type="revolute">
    <origin xyz="0.00000000 0.00000000 0.30002000" rpy="-1.57079633 -0.00000000 0.00000000" />
    <parent link="forearm_link" />
    <child link="wrist_link" />
    <axis xyz="0 0 1" />
    <limit lower="-3.141590" upper="3.141590" effort="4.100" velocity="3.141590" />
    <dynamics damping="0.54782342" friction="0.61477561" />
  </joint>
  <link name="wrist_link">
    <inertial>
      <origin xyz="0.03703017 -0.00003772 0.03004324" rpy="0 0 0" />
      <mass value="0.26791067" />
      <inertia ixx="0.0035256714" ixy="-0.0002252831" ixz="0.0000368980" iyy="0.0029978513" iyz="0.0000811238" izz="0.0026882308" />
    </inertial>
    <!-- Identified torque offset F0[4] = 0.132287 Nm (feed-forward term, add manually to your controller) -->
  </link>
  <joint name="wrist_angle" type="revolute">
    <origin xyz="0.00000000 0.00000000 0.00000000" rpy="1.57079633 -0.00000000 0.00000000" />
    <parent link="wrist_link" />
    <child link="gripper_link" />
    <axis xyz="0 0 1" />
    <limit lower="-1.745300" upper="2.146800" effort="4.100" velocity="3.141590" />
    <dynamics damping="0.03818428" friction="0.10468199" />
  </joint>
  <link name="gripper_link">
    <inertial>
      <origin xyz="0.01357285 0.00004795 0.02403773" rpy="0 0 0" />
      <mass value="0.21053414" />
      <inertia ixx="0.0018190688" ixy="0.0000052399" ixz="0.0000245200" iyy="0.0019631449" iyz="-0.0000023579" izz="0.0018085803" />
    </inertial>
    <!-- Identified torque offset F0[5] = -0.074745 Nm (feed-forward term, add manually to your controller) -->
  </link>
  <joint name="wrist_rotate" type="revolute">
    <origin xyz="0.00000000 0.00000000 0.00000000" rpy="-1.57079633 -0.00000000 0.00000000" />
    <parent link="gripper_link" />
    <child link="ee_arm" />
    <axis xyz="0 0 1" />
    <limit lower="-3.141590" upper="3.141590" effort="4.100" velocity="3.141590" />
    <dynamics damping="0.00738103" friction="0.00000044" />
  </joint>
  <link name="ee_arm">
    <inertial>
      <origin xyz="0.00311509 0.00008089 0.01124909" rpy="0 0 0" />
      <mass value="0.18460717" />
      <inertia ixx="0.0021360539" ixy="0.0000047251" ixz="0.0000010075" iyy="0.0021390874" iyz="0.0000015466" izz="0.0020711043" />
    </inertial>
    <!-- Identified torque offset F0[6] = -0.003198 Nm (feed-forward term, add manually to your controller) -->
  </link>
  <joint name="ee_arm" type="fixed">
    <origin xyz="0.13658000 0.0 0.0" rpy="0 0 0" />
    <parent link="ee_arm" />
    <child link="ee_link" />
  </joint>
  <link name="ee_link" />
</robot>