<?xml version="1.0" ?>
<robot name="viper300_sysid">
  <!-- Generated by phi_to_urdf 1.0 | phi: outputs/npy/traj_run_20260518_143818__sysid_feasible-v1-4__cfg-d8f86a93.npy -->
  <link name="base_link">
    <inertial>
      <mass value="0.0" />
      <inertia ixx="0" ixy="0" ixz="0" iyy="0" iyz="0" izz="0" />
    </inertial>
  </link>
  <joint name="waist" type="revolute">
    <origin xyz="0.00000000 0.00000000 0.12675000" rpy="0.00000000 -0.00000000 0.00000000" />
    <parent link="base_link" />
    <child link="waist_link" />
    <axis xyz="0 0 1" />
    <limit lower="-3.141590" upper="3.141590" effort="4.100" velocity="3.141590" />
    <dynamics damping="0.01197049" friction="0.08677199" />
  </joint>
  <link name="waist_link">
    <inertial>
      <origin xyz="0.00000000 0.00000000 0.00000000" rpy="0 0 0" />
      <mass value="0.00000100" />
      <inertia ixx="0.0003465303" ixy="0.0000000000" ixz="0.0000000000" iyy="0.0003465303" iyz="0.0000000000" izz="0.0006910606" />
    </inertial>
    <!-- Identified torque offset F0[1] = -0.002174 Nm (feed-forward term, add manually to your controller) -->
  </link>
  <joint name="shoulder" type="revolute">
    <origin xyz="0.00000000 -0.00000000 0.00000000" rpy="-1.57079633 -0.00000000 -1.37287599" />
    <parent link="waist_link" />
    <child link="upper_arm_link" />
    <axis xyz="0 0 1" />
    <limit lower="-1.876300" upper="1.989700" effort="10.600" velocity="2.610500" />
    <dynamics damping="0.00000000" friction="0.45077654" />
  </joint>
  <link name="upper_arm_link">
    <inertial>
      <origin xyz="0.00596062 1.04020635 0.03926819" rpy="0 0 0" />
      <mass value="0.00001294" />
      <inertia ixx="0.0004737763" ixy="-0.0000025911" ixz="-0.0000000979" iyy="0.0000393100" iyz="-0.0000170702" izz="0.0004731460" />
    </inertial>
    <!-- Identified torque offset F0[2] = -0.860807 Nm (feed-forward term, add manually to your controller) -->
  </link>
  <joint name="elbow" type="revolute">
    <origin xyz="0.29996732 -0.06015719 0.00000000" rpy="0.00000000 -0.00000000 -0.19792034" />
    <parent link="upper_arm_link" />
    <child link="forearm_link" />
    <axis xyz="0 0 1" />
    <limit lower="-2.152100" upper="1.570800" effort="10.600" velocity="2.610500" />
    <dynamics damping="0.00000000" friction="0.59285512" />
  </joint>
  <link name="forearm_link">
    <inertial>
      <origin xyz="-0.37280549 0.00660025 -0.06249259" rpy="0 0 0" />
      <mass value="0.26341194" />
      <inertia ixx="0.0000243052" ixy="0.0000000617" ixz="-0.0000037299" iyy="0.0000284646" iyz="0.0000000648" izz="0.0000214105" />
    </inertial>
    <!-- Identified torque offset F0[3] = -2.811904 Nm (feed-forward term, add manually to your controller) -->
  </link>
  <joint name="forearm_roll" type="revolute">
    <origin xyz="0.00000000 0.00000000 0.30002000" rpy="-1.57079633 -0.00000000 0.00000000" />
    <parent link="forearm_link" />
    <child link="wrist_link" />
    <axis xyz="0 0 1" />
    <limit lower="-3.141590" upper="3.141590" effort="4.100" velocity="3.141590" />
    <dynamics damping="0.00000000" friction="0.88451446" />
  </joint>
  <link name="wrist_link">
    <inertial>
      <origin xyz="-0.06440200 -0.00033221 0.01086675" rpy="0 0 0" />
      <mass value="0.03008773" />
      <inertia ixx="0.0013173044" ixy="0.0001836966" ixz="-0.0000524377" iyy="0.0001286976" iyz="0.0003471538" izz="0.0012458934" />
    </inertial>
    <!-- Identified torque offset F0[4] = 0.198195 Nm (feed-forward term, add manually to your controller) -->
  </link>
  <joint name="wrist_angle" type="revolute">
    <origin xyz="0.00000000 0.00000000 0.00000000" rpy="1.57079633 -0.00000000 0.00000000" />
    <parent link="wrist_link" />
    <child link="gripper_link" />
    <axis xyz="0 0 1" />
    <limit lower="-1.745300" upper="2.146800" effort="4.100" velocity="3.141590" />
    <dynamics damping="0.00215506" friction="0.12950430" />
  </joint>
  <link name="gripper_link">
    <inertial>
      <origin xyz="-0.01067273 0.00033277 -0.01541504" rpy="0 0 0" />
      <mass value="0.03005076" />
      <inertia ixx="0.0005513052" ixy="-0.0000204121" ixz="-0.0000848445" iyy="0.0004864745" iyz="-0.0000662651" izz="0.0002420639" />
    </inertial>
    <!-- Identified torque offset F0[5] = -0.155932 Nm (feed-forward term, add manually to your controller) -->
  </link>
  <joint name="wrist_rotate" type="revolute">
    <origin xyz="0.00000000 0.00000000 0.00000000" rpy="-1.57079633 -0.00000000 0.00000000" />
    <parent link="gripper_link" />
    <child link="ee_arm" />
    <axis xyz="0 0 1" />
    <limit lower="-3.141590" upper="3.141590" effort="4.100" velocity="3.141590" />
    <dynamics damping="0.00089973" friction="0.00000000" />
  </joint>
  <link name="ee_arm">
    <inertial>
      <origin xyz="0.00153594 0.00033277 0.00332058" rpy="0 0 0" />
      <mass value="0.03005076" />
      <inertia ixx="0.0000190633" ixy="0.0000000837" ixz="0.0000011060" iyy="0.0000190382" iyz="-0.0000012834" izz="0.0000021691" />
    </inertial>
    <!-- Identified torque offset F0[6] = -0.000536 Nm (feed-forward term, add manually to your controller) -->
  </link>
  <joint name="ee_arm" type="fixed">
    <origin xyz="0.13658000 0.0 0.0" rpy="0 0 0" />
    <parent link="ee_arm" />
    <child link="ee_link" />
  </joint>
  <link name="ee_link" />
</robot>